Workbook
Name Prefix: [1]คำนำหน้าชื่อ!$A$2:$A$6

Sheet Sheet1 (2)
A1: วันและเวลาที่สร้างรายงาน 2021-06-24 02:09:22.531453
A2: รหัสโรงเรียน | B2: ชื่อโรงเรียน | C2: เลขประจำตัวนักเรียน | D2: ชั้น | E2: ห้อง | F2: เลขประจำตัวนักเรียน | G2: เพศ | H2: คำนำหน้าชื่อ | I2: ชื่อ | J2: นามสกุล | K2: วันเกิด | L2: อายุ(ปี) | M2: น้ำหนัก | N2: ส่วนสูง
A3: 13022005 | B3: เตรียมอุดมศึกษาพัฒนาการ ปทุมธานี | C3: 1100401470161 | D3: ม.1 | E3: 1 | F3: 20431 | G3: ช | H3: เด็กชาย | I3: คีตกร | J3: สอนวิชา | K3: 03/06/2552 | L3: 12 | M3: 39 | N3: 156
A4: 13022005 | B4: เตรียมอุดมศึกษาพัฒนาการ ปทุมธานี | C4: 1101000241952 | D4: ม.1 | E4: 1 | F4: 20432 | G4: ช | H4: เด็กชาย | I4: จักรี | J4: ช่วงคิด | K4: 06/04/2552 | L4: 12 | M4: 58.5 | N4: 152
A5: 13022005 | B5: เตรียมอุดมศึกษาพัฒนาการ ปทุมธานี | C5: 1104200668359 | D5: ม.1 | E5: 1 | F5: 20433 | G5: ช | H5: เด็กชาย | I5: ฉัตรชนินทร์ | J5: รักษาวงศ์ | K5: 05/12/2551 | L5: 13 | M5: 38 | N5: 155
A6: 13022005 | B6: เตรียมอุดมศึกษาพัฒนาการ ปทุมธานี | C6: 1103101023278 | D6: ม.1 | E6: 1 | F6: 20434 | G6: ช | H6: เด็กชาย | I6: ชนะภัทร | J6: หิงประโคน | K6: 17/08/2551 | L6: 13 | M6: 37 | N6: 142
A7: 13022005 | B7: เตรียมอุดมศึกษาพัฒนาการ ปทุมธานี | C7: 1102900176481 | D7: ม.1 | E7: 1 | F7: 20435 | G7: ช | H7: เด็กชาย | I7: ชาคริส | J7: สิงห์มา | K7: 25/12/2551 | L7: 13 | M7: 43 | N7: 145
A8: 13022005 | B8: เตรียมอุดมศึกษาพัฒนาการ ปทุมธานี | C8: 1104200666429 | D8: ม.1 | E8: 1 | F8: 20437 | G8: ช | H8: เด็กชาย | I8: ณัฐภัทร | J8: เมืองแก้ว | K8: 25/11/2551 | L8: 13 | M8: 44 | N8: 160
A9: 13022005 | B9: เตรียมอุดมศึกษาพัฒนาการ ปทุมธานี | C9: 1138900035743 | D9: ม.1 | E9: 1 | F9: 20438 | G9: ช | H9: เด็กชาย | I9: แทนพงศ์ | J9: เอมสมุท | K9: 03/04/2552 | L9: 12 | M9: 51 | N9: 155
A10: 13022005 | B10: เตรียมอุดมศึกษาพัฒนาการ ปทุมธานี | C10: 1104200688333 | D10: ม.1 | E10: 1 | F10: 20439 | G10: ช | H10: เด็กชาย | I10: ธนกฤต | J10: สขะเศวต | K10: 03/05/2552 | L10: 12 | M10: 60 | N10: 150
A11: 13022005 | B11: เตรียมอุดมศึกษาพัฒนาการ ปทุมธานี | C11: 1100501710920 | D11: ม.1 | E11: 1 | F11: 20440 | G11: ช | H11: เด็กชาย | I11: ธราเทพ | J11: อุทัยแจ่ม | K11: 20/01/2552 | L11: 12 | M11: 46 | N11: 148
A12: 13022005 | B12: เตรียมอุดมศึกษาพัฒนาการ ปทุมธานี | C12: 1260401198827 | D12: ม.1 | E12: 1 | F12: 20443 | G12: ช | H12: เด็กชาย | I12: แผ่นฟ้า | J12: เคลลี่ | K12: 31/03/2552 | L12: 12 | M12: 35 | N12: 150
A13: 13022005 | B13: เตรียมอุดมศึกษาพัฒนาการ ปทุมธานี | C13: 1139700078431 | D13: ม.1 | E13: 1 | F13: 20444 | G13: ช | H13: เด็กชาย | I13: พนธกร | J13: วงศ์สุวัชร | K13: 22/12/2551 | L13: 13 | M13: 64.5 | N13: 163
A14: 13022005 | B14: เตรียมอุดมศึกษาพัฒนาการ ปทุมธานี | C14: 1103704356465 | D14: ม.1 | E14: 1 | F14: 20445 | G14: ช | H14: เด็กชาย | I14: พลภัทร | J14: อินทุรัตน์ | K14: 12/09/2551 | L14: 13 | M14: 36 | N14: 151
... A2611: 13022005 | B2611: เตรียมอุดมศึกษาพัฒนาการ ปทุมธานี | C2611: 1749900922559 | D2611: ม.6 | E2611: 10 | F2611: 19747 | G2611: ญ | H2611: นางสาว | I2611: อังสนา | J2611: ศรีแดงเกตุ | K2611: 21/10/2546 | L2611: 18 | M2611: 59 | N2611: 176

Sheet Sheet9
A1: ตารางสรุปยอดนักเรียน ณ วันที่ 2 พ.ค. 2569 ปีการศึกษา 2569(จริง) | P1: =TODAY() -> 46189
A2: ชั้น | B2: ห้อง
B3: 1 | C3: 2 | D3: 3 | E3: 4 | F3: 5 | G3: 6 | H3: 7 | I3: 8 | J3: 9 | K3: 10 | L3: 11 | M3: 12 | N3: 13
A4: ม.1 | B4: =COUNTBLANK(ม.1!D6:D45) -> 40 | C4: =COUNTBLANK(ม.1!D52:D92) -> 41 | D4: =COUNTBLANK(ม.1!D99:D139) -> 41 | E4: =COUNTBLANK(ม.1!D146:D186) -> 41 | F4: =COUNTBLANK(ม.1!D193:D233) -> 41 | G4: =COUNTBLANK(ม.1!D240:D280) -> 41 | H4: =COUNTBLANK(ม.1!D287:D327) -> 41 | I4: =COUNTBLANK(ม.1!D334:D375) -> 42 | J4: =COUNTBLANK(ม.1!D382:D423) -> 42 | K4: =COUNTBLANK(ม.1!D430:D470) -> 41 | L4: =COUNTBLANK(ม.1!D477:D511) -> 35 | M4: =COUNTBLANK(ม.1!D518:D530) -> 13 | N4: =COUNTBLANK(ม.1!D537:D578) -> 42 | O4: =SUM(B4:N4) -> 501
A5: ม.2 | B5: =COUNTBLANK(ม.2!D6:D45) -> 40 | C5: =COUNTBLANK(ม.2!D52:D90) -> 39 | D5: =COUNTBLANK(ม.2!D97:D134) -> 38 | E5: =COUNTBLANK(ม.2!D141:D180) -> 40 | F5: =COUNTBLANK(ม.2!D187:D226) -> 40 | G5: =COUNTBLANK(ม.2!D233:D270) -> 38 | H5: =COUNTBLANK(ม.2!D277:D315) -> 39 | I5: =COUNTBLANK(ม.2!D322:D359) -> 38 | J5: =COUNTBLANK(ม.2!D366:D405) -> 40 | K5: =COUNTBLANK(ม.2!D412:D450) -> 39 | L5: =COUNTBLANK(ม.2!D457:D491) -> 35 | M5: =COUNTBLANK(ม.2!D499:D525) -> 27 | N5: =COUNTBLANK(ม.2!D532:D571) -> 40 | O5: =SUM(B5:N5) -> 493
A6: ม.3 | B6: =COUNTBLANK(ม.3!D6:D45) -> 40 | C6: =COUNTBLANK(ม.3!D51:D89) -> 39 | D6: =COUNTBLANK(ม.3!D95:D133) -> 39 | E6: =COUNTBLANK(ม.3!D139:D178) -> 40 | F6: =COUNTBLANK(ม.3!D184:D224) -> 41 | G6: =COUNTBLANK(ม.3!D230:D269) -> 40 | H6: =COUNTBLANK(ม.3!D275:D313) -> 39 | I6: =COUNTBLANK(ม.3!D319:D358) -> 40 | J6: =COUNTBLANK(ม.3!D364:D403) -> 40 | K6: =COUNTBLANK(ม.3!D409:D447) -> 39 | L6: =COUNTBLANK(ม.3!D453:D486) -> 34 | M6: =COUNTBLANK(ม.3!D492:D513) -> 22 | O6: =SUM(B6:M6) -> 453
A7: ม.4 | B7: =COUNTBLANK(ม.4!D7:D33) -> 27 | C7: =COUNTBLANK(ม.4!D40:D80) -> 41 | D7: =COUNTBLANK(ม.4!D87:D126) -> 40 | E7: =COUNTBLANK(ม.4!D133:D173) -> 41 | F7: =COUNTBLANK(ม.4!D180:D219) -> 40 | G7: =COUNTBLANK(ม.4!D226:D266) -> 41 | H7: =COUNTBLANK(ม.4!D273:D312) -> 40 | I7: =COUNTBLANK(ม.4!D319:D360) -> 42 | J7: =COUNTBLANK(ม.4!D367:D404) -> 38 | K7: =COUNTBLANK(ม.4!D411:D449) -> 39 | L7: =COUNTBLANK(ม.4!D456:D498) -> 43 | O7: =SUM(B7:N7) -> 432
A8: ม.5 | B8: =COUNTBLANK(ม.5!D7:D18) -> 12 | C8: =COUNTBLANK(ม.5!D26:D65) -> 40 | D8: =COUNTBLANK(ม.5!D72:D112) -> 41 | E8: =COUNTBLANK(ม.5!D119:D157) -> 39 | F8: =COUNTBLANK(ม.5!D165:D200) -> 36 | G8: =COUNTBLANK(ม.5!D208:D245) -> 38 | H8: =COUNTBLANK(ม.5!D253:D292) -> 40 | I8: =COUNTBLANK(ม.5!D300:D338) -> 39 | J8: =COUNTBLANK(ม.5!D346:D382) -> 37 | K8: =COUNTBLANK(ม.5!D390:D427) -> 38 | L8: =COUNTBLANK(ม.5!D435:D474) -> 40 | O8: =SUM(B8:N8) -> 400
A9: ม.6 | B9: =COUNTBLANK(ม.6!D7:D28) -> 22 | C9: =COUNTBLANK(ม.6!D35:D73) -> 39 | D9: =COUNTBLANK(ม.6!D80:D121) -> 42 | E9: =COUNTBLANK(ม.6!D128:D169) -> 42 | F9: =COUNTBLANK(ม.6!D176:D215) -> 40 | G9: =COUNTBLANK(ม.6!D222:D261) -> 40 | H9: =COUNTBLANK(ม.6!D268:D305) -> 38 | I9: =COUNTBLANK(ม.6!D312:D350) -> 39 | J9: =COUNTBLANK(ม.6!D357:D394) -> 38 | K9: =COUNTBLANK(ม.6!D402:D438) -> 37 | L9: =COUNTBLANK(ม.6!D445:D481) -> 37 | O9: =SUM(B9:N9) -> 414
O10: =SUM(O4:O9) -> 2693

Sheet นักเรียนเข้าใหม่
A1: 4/6
A2: 2/4 | B2: เลขประจำตัว | G2: ห้อง
A3: 1/1 | B3: 13468 | G3: 3/1
A4: 1/2 | B4: 15551 | G4: 2/2
A5: 1/3 | B5: 15552 | G5: 2/2
A6: 2/2 | B6: 15553 | G6: 2/3
A7: 1/6 | B7: 15554 | G7: 2/9
A8: 4/2 | B8: 15555 | G8: 2/10
A9: 1/5 | B9: 15556 | G9: 3/1
A10: 2/6 | B10: 15557 | G10: 3/6
A11: 1/12 | B11: 15558 | G11: 3/6
A12: 1/4 | B12: 15559 | G12: 3/10
A13: 1/1 | B13: 15560 | G13: 5/4
A14: 1/7 | B14: 15561 | G14: 5/5
A15: 13 | B15: 15562 | G15: 5/5
A18: รายชื่อนักเรียนเข้าใหม่ ภาคเรียนที่2 ปีการศึกษา 2555
A19: ลำดับที่ | B19: เลขประจำตัว | G19: ห้อง
A20: 1 | B20: 15563 | G20: 4/4
A21: 2 | B21: 15564 | G21: 5/3 | J21: 15566
A22: 3 | B22: 15565 | G22: 1/7
A24: รายชื่อนักเรียนเข้าใหม่ ภาคเรียนที่ 1 ปีการศึกษา 2556
A25: ที่ | G25: ห้อง
A26: 5 | B26: 15566 | G26: 1/1
A27: 6 | B27: 15567 | G27: 1/1
A28: 7 | B28: 15568 | G28: 1/1
A29: 8 | B29: 15569 | G29: 1/1
A30: 9 | B30: 15570 | G30: 1/1
A31: 10 | B31: 15571 | G31: 1/1
A32: 11 | B32: 15572 | G32: 1/1
A33: 12 | B33: 15573 | G33: 1/1
A34: 13 | B34: 15574 | G34: 1/1
A35: 14 | B35: 15575 | G35: 1/1
A36: 15 | B36: 15576 | G36: 1/1
A37: 16 | B37: 15577 | G37: 1/1
... A467: 43 | B467: 16007 | G467: 1/10
A468: 13 | B468: 16008 | G468: 1/11
A469: 1 | B469: 16009 | G469: 1/11
A470: 2 | B470: 16010 | G470: 1/11
A471: 3 | B471: 16011 | G471: 1/11
A472: 4 | B472: 16012 | G472: 1/11
...

Sheet ม.1
A1: โรงเรียนเตรียมอุดมศึกษาพัฒนาการ ปทุมธานี
B2: รายชื่อนักเรียน ปีการศึกษา 2569 ภาคเรียนที่ 1 ชั้น ม. 1 ห้องที่ 1 คณะรักชาติ (สีแดง)
A3: วิชา..............................................
A4: ครูที่ปรึกษา : 1.นางสาวอภิชญา ธนาวิวัฒน์ 2.สาวอรัญญา หวังมีอาจ
A5: ที่ | B5: เลขประจำตัว | C5: ชื่อ นามสกุล
A6: 1 | B6: 23576 | C6: ด.ช.คุณานนท์ นาโคกูล
A7: 2 | B7: 23577 | C7: ด.ช.จารุเดช จิระสุนันทชัย
A8: 3 | B8: 23578 | C8: ด.ช.ชนะกัณต์ อนุกูล | J8: ขอใบเปลี่ยนชื่อพ่อ
A9: 4 | B9: 23579 | C9: ด.ช.ชยกร เมฆศิลป์
A10: 5 | B10: 23580 | C10: ด.ช.ชยดล เมฆศิลป์
A11: 6 | B11: 23581 | C11: ด.ช.ณฐพล คำนา
A12: 7 | B12: 23582 | C12: ด.ช.ณัฐนนท์ ประดิษฐ์
A13: 8 | B13: 23583 | C13: ด.ช.ณัฐพล ชัยสิทธิ์
A14: 9 | B14: 23584 | C14: ด.ช.ธนศักดิ์ แจ่มประเสริฐ
A15: 10 | B15: 23585 | C15: ด.ช.ธาราเทพ มีสมบัติ
A16: 11 | B16: 23586 | C16: ด.ช.นพดล รักธรรม
A17: 12 | B17: 23587 | C17: ด.ช.นวพล กล่ำทรัพย์
A18: 13 | B18: 23588 | C18: ด.ช.ปัญญวัฒน์ ชูสิงแค
A19: 14 | B19: 23589 | C19: ด.ช.ภีรเดช มิ่งขวัญยืน
A20: 15 | B20: 23590 | C20: ด.ช.ภูมิกร ระงับภัย
... A35: 30 | B35: 23606 | C35: ด.ญ.ปภาวรินท์ โสดา
A36: 31 | B36: 23607 | C36: ด.ญ.เพชรไพลิน ทรัพย์วัฒน์ | J36: ขอทะเบียนบ้านนักเรียน
A37: 32 | B37: 23608 | C37: ด.ญ.แพรไหม สุขเจริญ
A38: 33 | B38: 23609 | C38: ด.ญ.ภัคควิภา คงประหัส
A39: 34 | B39: 23610 | C39: ด.ญ.วิภาวดี ใบกุหลาบ
A40: 35 | B40: 23611 | C40: ด.ญ.สรัณณัฏฐ์ บูชา
A41: 36 | B41: 23612 | C41: ด.ญ.สุพาวดี พิมพ์เสนา
A42: 37 | B42: 23613 | C42: ด.ญ.อชิรญา เจริญมาศ
A43: 38 | B43: 23614 | C43: ด.ญ.อภิญญา อามีน
A44: 39 | B44: 23615 | C44: ด.ญ.อริสา ชาวเดิร
A45: 40 | B45: 23616 | C45: ด.ญ.ไอลดา กงวงษ์
A47: โรงเรียนเตรียมอุดมศึกษาพัฒนาการ ปทุมธานี
B48: รายชื่อนักเรียน ปีการศึกษา 2569 ภาคเรียนที่ 1 ชั้น ม. 1 ห้องที่ 2 คณะผดุงศาสน์ (สีเหลือง)
A49: วิชา..............................................
A50: ครูที่ปรึกษา : 1.นางสาวอุมารินทร์ แสนเพ็งเคน 2.นางสาวฐาปนี ชื่นตา
A51: ที่ | B51: เลขประจำตัว | C51: ชื่อ นามสกุล
A52: 1 | B52: 23617 | C52: ด.ช.กันตพล สมเด็จ
A53: 2 | B53: 23618 | C53: ด.ช.ชัยชนะ วงษ์ราษฎร์
A54: 3 | B54: 23619 | C54: ด.ช.โชติพัฒน์ คำผลศิริ
A55: 4 | B55: 23620 | C55: ด.ช.ฐิติวัชร์ ครัวกลาง
...

Sheet Sheet10
A1: ชั้นเคลื่อน ภาคเรียนที่ 2 ปีการศึกษา 2565
A2: 1 | B2: 21621 | C2: ด.ญ.น้ำเพชร สารัชชู | D2: ม.1/3
A3: 2 | B3: 21622 | C3: ด.ญ.อมรสิริ นาสิลพร้อม | D3: ม.1/11
A4: ชั้นเคลื่อน ภาคเรียนที่ 1 ปีการศึกษา 2566
A5: 1 | B5: 22210 | C5: ด.ญ.รภัสรดา จรัสเรือง | D5: ม.2/1
A6: 2 | B6: 22211 | C6: ด.ญ.จินจุฑา บุญพึ่ง | D6: ม.2/2
A7: 3 | B7: 22212 | C7: ด.ช.พนากรณ์ กิจจานุลักษณ์ | D7: ม.2/3
A8: 4 | B8: 22213 | C8: ด.ญ.กนกอร จันสา | D8: ม.2/3
A9: 5 | B9: 22214 | C9: ด.ญ.ลลิตวดี ก่อกิจฤทธิชัย | D9: ม.2/3
A10: 6 | B10: 21231 | C10: ด.ช.ชินปกรณ์ พรหมบังเกิด | D10: ม.2/5
A11: 7 | B11: 22215 | C11: ด.ช.พีรธัช จันตา | D11: ม.2/5
A12: 8 | B12: 22216 | C12: ด.ญ.ปิยะฉัตร ทองสุทธ์ | D12: ม.2/6
A13: 9 | B13: 22217 | C13: ด.ญ.ปุญญิศา สุบงกฏ | D13: ม.2/7
A14: 10 | B14: 22218 | C14: ด.ญ.สุชาดา นพดล | D14: ม.2/7
A15: 11 | B15: 22219 | C15: ด.ญ.ศุภิสรา นรสาร | D15: ม.2/8
A16: 30 | B16: 22238 | C16: ด.ช.พีรพัฒน์ สุขผล | D16: ม.2/1
... A18: 36 | B18: 22243 | C18: ด.ช.หัสดินทร์ อุ่นสอาด | D18: ม.2/4
A19: ชั้นเคลื่อน ภาคเรียนที่2 ปีการศึกษา 2566
A20: 10 | B20: 22253 | C20: เด็กชายกฤตมงคล มงคุณ | D20: 2/2
A21: 11 | B21: 22254 | C21: เด็กชายกฤตเมธ โคตรจันทึก | D21: 2/4
A22: 12 | B22: 22255 | C22: เด็กชายอาชวิน ประดิษฐศิลป์ | D22: 2/6
A23: ชั้นเคลื่อน ภาคเรียนที่1 ปีการศึกษา 2567

Sheet ม.2
A1: โรงเรียนเตรียมอุดมศึกษาพัฒนาการ ปทุมธานี
B2: รายชื่อนักเรียน ปีการศึกษา 2569 ภาคเรียนที่ 1 ชั้น ม. 2 ห้องที่ 1 คณะรักชาติ (สีแดง)
A3: วิชา..............................................
A4: ครูที่ปรึกษา : 1.นางสาวนฤมล วาชัยยุง
A5: ที่ | B5: เลขประจำตัว | C5: ชื่อ นามสกุล
A6: 1 | B6: 22871 | C6: ด.ช.กวี บุญทับ
A7: 2 | B7: 22872 | C7: ด.ช.จิรภัทร อารมย์สุข
A8: 3 | B8: 22873 | C8: ด.ช.ณัฐภูมิ ไกรเสือ
A9: 4 | B9: 22874 | C9: ด.ช.ตฤณจร กางร่มกลาง
A10: 5 | B10: 22875 | C10: ด.ช.เตชพัฒน์ วงศ์รอด
A11: 6 | B11: 22876 | C11: ด.ช.ธนชัย หมายศรี
A12: 7 | B12: 22877 | C12: ด.ช.ปัณณวิชญ์ อินทโลหิต
A13: 8 | B13: 22878 | C13: ด.ช.พัชรพล ทองเสือ
A14: 9 | B14: 22879 | C14: ด.ช.ภูชนะ เกิดเมือง
A15: 10 | B15: 22880 | C15: ด.ช.มณัฐภูมิ ทับเหมือน
A16: 11 | B16: 22881 | C16: ด.ช.เมฆา เพ็ชรทิพย์
A17: 12 | B17: 22882 | C17: ด.ช.วทัญญู ทัดภูธร
... A45: 40 | B45: 24174 | C45: ด.ญ.พาขวัญ นักเป่า
A47: โรงเรียนเตรียมอุดมศึกษาพัฒนาการ ปทุมธานี
B48: รายชื่อนักเรียน ปีการศึกษา 2569 ภาคเรียนที่ 1 ชั้น ม. 2 ห้องที่ 2 คณะเทิดกษัตริย์ (สีฟ้า)
A49: วิชา..............................................
A50: ครูที่ปรึกษา : 1.นางสาวธัญญารัตน์ ไหวพรม 2.นายธนรัตน์ ทองวิชิต
A51: ที่ | B51: เลขประจำตัว | C51: ชื่อ นามสกุล
A52: 1 | B52: 22912 | C52: ด.ช.กันต์รพี สิงห์โตทอง
A53: 2 | B53: 22914 | C53: ด.ช.จักริน อินทร์เพชร
A54: 3 | B54: 22915 | C54: ด.ช.ณจฐพงษ อยู่ลอง
A55: 4 | B55: 22916 | C55: ด.ช.ต้นกล้า หว่าลิ่งต๊ะ
A56: 5 | B56: 22917 | C56: ด.ช.ทินวุฒิ แซ่เซี๊ยะ
A57: 6 | B57: 22918 | C57: ด.ช.ธนวินท์ ขุนทอง
A58: 7 | B58: 22919 | C58: ด.ช.นภัทร หมอกผัน
A59: 8 | B59: 22920 | C59: ด.ช.ปธิภัทร พลเยี่ยม
A60: 9 | B60: 22921 | C60: ด.ช.พชร อังคะหิรัญ
A61: 10 | B61: 22922 | C61: ด.ช.พัชรพล หรั่งฤทธิ์
A62: 11 | B62: 22923 | C62: ด.ช.ภัทรดนัย ขุนทอง
A63: 12 | B63: 22924 | C63: ด.ช.ภาสิทธิ์ ดวงสิมา
... A90: 39 | B90: 24181 | C90: ด.ญ.ณัฏฐณิชา พูลลาภ
A92: โรงเรียนเตรียมอุดมศึกษาพัฒนาการ ปทุมธานี
B93: รายชื่อนักเรียน ปีการศึกษา 2569 ภาคเรียนที่ 1 ชั้น ม. 2 ห้องที่ 3 คณะรักชาติ (สีแดง)
A94: วิชา..............................................
A95: ครูที่ปรึกษา : 1.นายกิตติพงษ์ วรประทีป
...

Sheet ม.3
A1: โรงเรียนเตรียมอุดมศึกษาพัฒนาการ ปทุมธานี
B2: รายชื่อนักเรียน ปีการศึกษา 2569 ภาคเรียนที่ 1 ชั้น ม. 3 ห้องที่ 1 คณะใฝ่คุณธรรม (สีม่วง)
A3: วิชา..............................................
A4: ครูที่ปรึกษา : 1.นางสาวกรรณิการ์ นันบุญมา 2.นางสาวนิรามัย เอกนัย
A5: ที่ | B5: เลขประจำตัว | C5: ชื่อ นามสกุล
A6: 1 | B6: 22257 | C6: ด.ช.จุลพัฒน์ โสภณ
A7: 2 | B7: 22258 | C7: ด.ช.ณัฐพล เกตุทัต
A8: 3 | B8: 22259 | C8: ด.ช.ณัฐภัทร สุดทอง
A9: 4 | B9: 22260 | C9: ด.ช.เตชิต มีใหม่
A10: 5 | B10: 22261 | C10: ด.ช.เตชิต เหลืองอ่อน
A11: 6 | B11: 22262 | C11: ด.ช.ทิวา เทพทองอินทร์
A12: 7 | B12: 22263 | C12: ด.ช.ธิติภัทร จรรยา
A13: 8 | B13: 22264 | C13: ด.ช.ธีรภัทร พวงมาลัย
A14: 9 | B14: 22265 | C14: ด.ช.ปิยะ ศรีสวัสดิ์
A15: 10 | B15: 22266 | C15: ด.ช.พสิษฐ์ ปาริชาติอินทราณี
A16: 11 | B16: 22267 | C16: ด.ช.ภาราดิน ไชยานนท์
A17: 12 | B17: 22268 | C17: ด.ช.เมธาสิทธิ์ เล็กน้อยวงค์
... A45: 40 | B45: 23526 | C45: ด.ญ.ณัชชา ราชวัฒน์
A46: โรงเรียนเตรียมอุดมศึกษาพัฒนาการ ปทุมธานี
B47: รายชื่อนักเรียน ปีการศึกษา 2569 ภาคเรียนที่ 1 ชั้น ม. 3 ห้องที่ 2 คณะรักชาติ (สีแดง)
A48: วิชา..............................................
A49: ครูที่ปรึกษา : 1.นายมานัส เดชไชย
A50: ที่ | B50: เลขประจำตัว | C50: ชื่อ นามสกุล
A51: 1 | B51: 22297 | C51: ด.ช.กรภัค พลอยเงิน
A52: 2 | B52: 22298 | C52: ด.ช.จักรกฤษณ์ กลั้วพิมาย
A53: 3 | B53: 22299 | C53: ด.ช.จิรกิตติพัฒน์ อ่อนเหล่
A54: 4 | B54: 22300 | C54: ด.ช.โชติกุลชัย ไผ่สีสุก
A55: 5 | B55: 22301 | C55: ด.ช.ณฐกร บาลี
A56: 6 | B56: 22302 | C56: ด.ช.ณัฐพงษ์ รักธรรม
A57: 7 | B57: 22303 | C57: ด.ช.เดชาวัตร จงดี
A58: 8 | B58: 22304 | C58: ด.ช.นภัทร สุขแสงดาว
A59: 9 | B59: 22305 | C59: ด.ช.ปัญธวัฒน์ ศิรรมย์ธนาพร
A60: 10 | B60: 22306 | C60: ด.ช.พชร ยอมิน
A61: 11 | B61: 22307 | C61: ด.ช.พัชรพล รัตนสุวรรณ
A62: 12 | B62: 22308 | C62: ด.ช.พัสกร วอนวัน
... A89: 39 | B89: 23528 | C89: ด.ญ.ชญาภา ดาวเรือง
A90: โรงเรียนเตรียมอุดมศึกษาพัฒนาการ ปทุมธานี
B91: รายชื่อนักเรียน ปีการศึกษา 2569 ภาคเรียนที่ 1 ชั้น ม. 3 ห้องที่ 3 คณะเทิดกษัตริย์ (สีฟ้า)
A92: วิชา..............................................
A93: ครูที่ปรึกษา : 1.นางสาวช่อทิพย์ พิมพ์สอน 2.นางสาวชลธิชา จันสา
...

Sheet ม.368
A1: โรงเรียนเตรียมอุดมศึกษาพัฒนาการ ปทุมธานี
B2: รายชื่อนักเรียน ปีการศึกษา 2568 ภาคเรียนที่ 2 ชั้น ม. 3 ห้องที่ 1 คณะรักชาติ (สีแดง) | D2: รายชื่อนักเรียน ปีการศึกษา 2568 ภาคเรียนที่ 2 ชั้น ม. 3 ห้องที่ 1 คณะรักชาติ (สีแดง)
A3: วิชา..............................................
A4: ครูที่ปรึกษา : 1.นายมานัส เดชไชย 2.นางสาวปนิตา บังทอง
A5: ที่ | B5: เลขประจำตัว | C5: ชื่อ นามสกุล | D5: เลขประจำตัว
A6: 1 | B6: 21629 | C6: ด.ช.กวี โต๊ะแอ | D6: 21629
A7: 2 | B7: 21630 | C7: ด.ช.กิตติกรณ์ แสงรส | D7: 21630
A8: 3 | B8: 21631 | C8: ด.ช.ไกรวิชญ์ ชารี | D8: 21631
A9: 4 | B9: 21632 | C9: ด.ช.ชิษณุพงศ์ รักใคร่ | D9: 21632
A10: 5 | B10: 21633 | C10: ด.ช.ถิรวัฒน์ สมชื่อ | D10: 21633
A11: 6 | B11: 21634 | C11: ด.ช.ธนกร สืบสิงห์ | D11: 21634
A12: 7 | B12: 21635 | C12: ด.ช.นัฐพร ชมมณฑา | D12: 21635
A13: 8 | B13: 21636 | C13: ด.ช.พีรพล มีเเสง | D13: 21636
A14: 9 | B14: 21637 | C14: ด.ช.พีรพัฒน์ เเก่นกลาง | D14: 21637
A15: 10 | B15: 21639 | C15: ด.ช.ภานุวัฒน์ แย้มกลิ่น | D15: 21639
A16: 11 | B16: 21640 | C16: ด.ช.ภูรินทร์ เลื่องลือ | D16: 21640
A17: 12 | B17: 21641 | C17: ด.ช.ภูวดล คำสุขุม | D17: 21641
... A44: 39 | B44: 21668 | C44: ด.ญ.อภิญญา ทัศนเวช | D44: 21668
A45: โรงเรียนเตรียมอุดมศึกษาพัฒนาการ ปทุมธานี
B46: รายชื่อนักเรียน ปีการศึกษา 2568 ภาคเรียนที่ 2 ชั้น ม. 3 ห้องที่ 2 คณะพัฒนาไทย (สีเขียว) | D46: รายชื่อนักเรียน ปีการศึกษา 2568 ภาคเรียนที่ 2 ชั้น ม. 3 ห้องที่ 2 คณะพัฒนาไทย (สีเขียว)
A47: วิชา..............................................
A48: ครูที่ปรึกษา : 1.นางสาววนิดา ใจสา 2.นายศุภชัย แสงเพชร
A49: ที่ | B49: เลขประจำตัว | C49: ชื่อ นามสกุล | D49: เลขประจำตัว
A50: 1 | B50: 21669 | C50: ด.ช.จิรพัฒน์ วัฒนวงษ์ | D50: 21669
A51: 2 | B51: 21670 | C51: ด.ช.เจริญเทพ มหารัตน์ไพบูลย์ | D51: 21670
A52: 3 | B52: 21671 | C52: ด.ช.ชัยรัตน์ เติมประเสริฐสกุล | D52: 21671
A53: 4 | B53: 21672 | C53: ด.ช.ณฐพล ทองพานิชย์ | D53: 21672
A54: 5 | B54: 21673 | C54: ด.ช.ณัฐนันท์ เเทนรินทร์ | D54: 21673
A55: 6 | B55: 21674 | C55: ด.ช.ณัฐพัฒน์ คาถา | D55: 21674
A56: 7 | B56: 21675 | C56: ด.ช.ธนกฤต เจริญใจ | D56: 21675
A57: 8 | B57: 21676 | C57: ด.ช.ธนวัฒน์ สาเเหรกทอง | D57: 21676
A58: 9 | B58: 21677 | C58: ด.ช.นภัทร อริยมาธากุล | D58: 21677
A59: 10 | B59: 21678 | C59: ด.ช.นิติภูมิ มูฮำหมัดรอโซน | D59: 21678
A60: 11 | B60: 21679 | C60: ด.ช.ปริทัศน์ จ่างเเสง | D60: 21679
A61: 12 | B61: 21681 | C61: ด.ช.พีรวัฒน์ พันบุบผา | D61: 21681
... A84: 35 | B84: 21704 | C84: ด.ญ.สุพนิตา พรมแก้ว | D84: 21704
A85: 36 | B85: 21705 | C85: ด.ญ.สุภาภรณ์ แก้วศิลปการ | D85: 21705 | J85: ด.ญ.สุภาภรณ์ ลุงอ้วน
A86: 37 | B86: 21706 | C86: ด.ญ.อติกานต์ ม้าสุวรรณ | D86: 21706
A87: 38 | B87: 21708 | C87: ด.ญ.อาทิตยา โห้งาม | D87: 21708
A88: 39 | B88: 23546 | C88: ด.ญ.โชติกา พงศ์ภัคปัญญา | D88: 23546
...

Sheet ม.367
A1: โรงเรียนเตรียมอุดมศึกษาพัฒนาการ ปทุมธานี
B2: รายชื่อนักเรียน ปีการศึกษา 2567 ภาคเรียนที่ 2 ชั้น ม. 3 ห้องที่ 1 คณะผดุงศาสน์ (สีเหลือง)
A3: วิชา..............................................
A4: ครูที่ปรึกษา : 1.นางสาวชลธิชา จันสา 2.นางสาวธัญญารัตน์ ไหวพรม
A5: ที่ | B5: เลขประจำตัว | C5: ชื่อ นามสกุล
A6: 1 | B6: 21093 | C6: ด.ช.กฤษ ใจเย็น
A7: 2 | B7: 21095 | C7: ด.ช.ชยพล ต้นทองคำ
A8: 3 | B8: 21096 | C8: ด.ช.ชิณเขตต์ ภูผาคุณ
A9: 4 | B9: 21097 | C9: ด.ช.ทานุทัต นุ้ยจำนัล
A10: 5 | B10: 21098 | C10: ด.ช.ธนโชติ ศรีสุวรรณ
A11: 6 | B11: 21101 | C11: ด.ช.ภาคภูมิ สุภักดี
A12: 7 | B12: 21102 | C12: ด.ช.ภาคภูมิ อารมคง
A13: 8 | B13: 21103 | C13: ด.ช.ภานุเดช สมพงษ์
A14: 9 | B14: 21104 | C14: ด.ช.วรวิทย์ ศิริ
A15: 10 | B15: 21105 | C15: ด.ช.วุฒิภัทร จันทร์เทศ
A16: 11 | B16: 21106 | C16: ด.ช.สถิรพันธ์ แนวโสภา
A17: 12 | B17: 21107 | C17: ด.ช.สุทธินัย กงนะ
... A38: 33 | B38: 22863 | C38: ด.ญ.อันดา กลิ่นน้ำเงิน
A39: โรงเรียนเตรียมอุดมศึกษาพัฒนาการ ปทุมธานี
B40: รายชื่อนักเรียน ปีการศึกษา 2567 ภาคเรียนที่ 2 ชั้น ม. 3 ห้องที่ 2 คณะใฝ่คุณธรรม (สีม่วง)
A41: วิชา..............................................
A42: ครูที่ปรึกษา : 1.นางสาวสิริมาวีร์ สิงห์สูง 2.นายธิติพงศ์ พิกุลขาว
A43: ที่ | B43: เลขประจำตัว | C43: ชื่อ นามสกุล
A44: 1 | B44: 21128 | C44: ด.ช.ฐนพณ บุญช่วย
A45: 2 | B45: 21129 | C45: ด.ช.ธนพล ร่องรัตน์
A46: 3 | B46: 21130 | C46: ด.ช.ธนะกฤต ไตรวิลาวัณย์
A47: 4 | B47: 21131 | C47: ด.ช.ธรประกาย อินทหอม
A48: 5 | B48: 21132 | C48: ด.ช.ปภาวิน ขจีจิตร
A49: 6 | B49: 21133 | C49: ด.ช.ปริยะ อ่องสอาด
A50: 7 | B50: 21134 | C50: ด.ช.ภูมิทัศน์ ศรีทอง
A51: 8 | B51: 21135 | C51: ด.ช.มนตรี สาระบุตร
A52: 9 | B52: 21136 | C52: ด.ช.รณกร สีสุข
A53: 10 | B53: 21137 | C53: ด.ช.วรณัฐ ภาโส
A54: 11 | B54: 21138 | C54: ด.ช.วิทวัส จันทะคัด
A55: 12 | B55: 21139 | C55: ด.ช.ศุภฤกษ์ วรรณเศรณีรักษ์
... A80: 37 | B80: 22846 | C80: ด.ญ.สุรัสวดี ศรีสุพรรณ
A82: โรงเรียนเตรียมอุดมศึกษาพัฒนาการ ปทุมธานี
B83: รายชื่อนักเรียน ปีการศึกษา 2567 ภาคเรียนที่ 2 ชั้น ม. 3 ห้องที่ 3 คณะรักชาติ (สีแดง)
A84: วิชา..............................................
A85: ครูที่ปรึกษา : 1.นางสาวนริสรา สุขตาม 2.นางสาวกรรณิการ์ นันบุญมา
...

Sheet Sheet8
A1: จ่ายเงินค่ารูป 2565
A2: ห้อง | B2: จำวนวคน | C2: จำนวนเงิน | D2: ลงชื่อผู้ส่ง | E2: วันที่ส่ง
A3: ม.3/1
A4: ม.3/2
A5: ม.3/3
A6: ม.3/4
A7: ม.3/5
A8: ม.3/6
A9: ม.3/7
A10: ม.3/8
A11: ม.3/9
A12: ม.3/10
A13: ม.3/11
A14: ม.3/12
... A24: ม.6/9

Sheet ม.366
A1: โรงเรียนเตรียมอุดมศึกษาพัฒนาการ ปทุมธานี
A2: รายชื่อนักเรียน ปีการศึกษา 2566 ภาคเรียนที่ 2 ชั้น ม. 3 ห้องที่ 1 คณะรักชาติ (สีแดง)
A3: รายชื่อ..............................................
A4: ครูที่ปรึกษา : 1.นางสาวชลธิชา จันสา 2.นางจิรภาภรณ์ วงศ์กาญจนฉัตร
A5: ที่ | B5: เลขประจำตัว | C5: ชื่อ นามสกุล
A6: 1 | B6: 20432 | C6: ด.ช.จักรี ช่างคิด
A7: 2 | B7: 20433 | C7: ด.ช.ฉัตรชนินทร์ รักษาวงศ์
A8: 3 | B8: 20434 | C8: ด.ช.ชนะภัทร หิงประโคน
A9: 4 | B9: 20436 | C9: ด.ช.ณัฏฐกรณ์ ขันแก้ว
A10: 5 | B10: 20437 | C10: ด.ช.ณัฐภัทร​ เมือง​แก้ว
A11: 6 | B11: 20438 | C11: ด.ช.เเทนพงศ์ เอมสมุท
A12: 7 | B12: 20439 | C12: ด.ช.ธนกฤต สุขะเศวต
A13: 8 | B13: 20440 | C13: ด.ช.ธราเทพ อุทัยแจ่ม
A14: 9 | B14: 20443 | C14: ด.ช.แผ่นฟ้า เคลลี่
A15: 10 | B15: 20444 | C15: ด.ช.พนธกร วงศ์สุวัชร์
A16: 11 | B16: 20446 | C16: ด.ช.พสิษฐ์ แสงศรี
A17: 12 | B17: 20447 | C17: ด.ช.พัลลภ โป๊ะแก้ว
... A36: 31 | B36: 20468 | C36: ด.ญ.สุชญา เชิดชูวงศ์สกุล
A37: 32 | B37: 20469 | C37: ด.ญ.ชาลิสา ศรีกระสินธุ์ | L37: ด.ญ.สุธิดา ศรีกระสินธุ์
A38: 33 | B38: 20470 | C38: ด.ญ.เพทาย เจริญศิริ
A39: 34 | B39: 20471 | C39: ด.ญ.อติพร เพ็ญวิจิตร
A40: 35 | B40: 20472 | C40: ด.ญ.อาริสา วารินกุด
A41: 36 | B41: 20473 | C41: ด.ญ.อินทริยา มณีเติม
A42: 37 | B42: 21588 | C42: ด.ญ.อัจฉรา คงบันนัก
A43: 38 | B43: 22223 | C43: ด.ญ.พิมพ์ดาว ปริญญาศุภมาศ
A44: โรงเรียนเตรียมอุดมศึกษาพัฒนาการ ปทุมธานี
B45: รายชื่อนักเรียน ปีการศึกษา 2566 ภาคเรียนที่ 2 ชั้น ม. 3 ห้องที่ 2 คณะเทิดกษัตริย์ (สีฟ้า)
A46: รายชื่อ..............................................
A47: ครูที่ปรึกษา : 1.นางสาวกมลทิพย์ เอี่ยมสอาด 2. นางสาวช่อทิพย์ พิมพ์สอน
A48: ที่ | B48: เลขประจำตัว | C48: ชื่อ นามสกุล
A49: 1 | B49: 20474 | C49: ด.ช.จิตรกรานต์ สรวยกรุ่น
A50: 2 | B50: 20475 | C50: ด.ช.ชญานนท์ บุญประเสริฐ
A51: 3 | B51: 20477 | C51: ด.ช.ณัฐพล สาหร่ายกลาง
A52: 4 | B52: 20478 | C52: ด.ช.ตี -
A53: 5 | B53: 20480 | C53: ด.ช.ธิติกร เอี่ยมสอาด
A54: 6 | B54: 20482 | C54: ด.ช.ปุณยริชย์ สินธุเสน
A55: 7 | B55: 20483 | C55: ด.ช.พีรชา ประเสริฐสุข
A56: 8 | B56: 20484 | C56: ด.ช.มงคลรัตน์ แซ่เล้า
A57: 9 | B57: 20485 | C57: ด.ช.วายุ ทองกัญญา
A58: 10 | B58: 20486 | C58: ด.ช.วิษณุ สุริยะ
...

Sheet Sheet1 (3)
A1: ระดับ | B1: ชั้น | C1: ห้อง | D1: ปีการศึกษา | E1: ภาคเรียน | F1: แผน | G1: เลขที่ | H1: กลุ่ม | I1: สถานะนักเรียน | J1: เลขประจำตัว | K1: คำนำหน้า | L1: ชื่อ | M1: นามสกุล | N1: เลขประชาชน | O1: เลขประจำตัว
A2: มัธยมต้น | B2: ม.3 | C2: 1 | D2: 2568 | E2: 2 | F2: 0 | G2: 1 | I2: จบการศึกษา | J2: 21629 | K2: นาย | L2: กวี | M2: โต๊ะแอ | N2: 1104301276073 | O2: 21629
A3: มัธยมต้น | B3: ม.3 | C3: 2 | D3: 2568 | E3: 2 | F3: 0 | G3: 1 | I3: จบการศึกษา | J3: 21669 | K3: นาย | L3: จิรพัฒน์ | M3: วัฒนวงษ์ | N3: 1104100049142 | O3: 21669
A4: มัธยมต้น | B4: ม.3 | C4: 3 | D4: 2568 | E4: 2 | F4: 0 | G4: 1 | I4: จบการศึกษา | J4: 21710 | K4: นาย | L4: กันต์นธีร์ | M4: แถมมุลตรี | N4: 1104200747291 | O4: 21710
A5: มัธยมต้น | B5: ม.3 | C5: 4 | D5: 2568 | E5: 2 | F5: 0 | G5: 1 | I5: จบการศึกษา | J5: 21749 | K5: นาย | L5: กสินชัย | M5: ครึมยะราช | N5: 1102004180274 | O5: 21749
A6: มัธยมต้น | B6: ม.3 | C6: 5 | D6: 2568 | E6: 2 | F6: 0 | G6: 1 | I6: จบการศึกษา | J6: 21790 | K6: นาย | L6: กาณฑ์ฐภัชภ์ | M6: ธีรคุปต์ | N6: 1102700850405 | O6: 21790
A7: มัธยมต้น | B7: ม.3 | C7: 6 | D7: 2568 | E7: 2 | F7: 0 | G7: 1 | I7: จบการศึกษา | J7: 21829 | K7: นาย | L7: กฤตพล | M7: พึ่งสว่าง | N7: 1279800278369 | O7: 21829
A8: มัธยมต้น | B8: ม.3 | C8: 7 | D8: 2568 | E8: 2 | F8: 0 | G8: 1 | I8: จบการศึกษา | J8: 21869 | K8: นาย | L8: กิตติกร | M8: แสงใหญ่ | N8: 1260401218259 | O8: 21869
A9: มัธยมต้น | B9: ม.3 | C9: 8 | D9: 2568 | E9: 2 | F9: 0 | G9: 1 | I9: จบการศึกษา | J9: 21909 | K9: เด็กชาย | L9: กิตติชัย | M9: แก้วฉาย | N9: 1104200786297 | O9: 21909
A10: มัธยมต้น | B10: ม.3 | C10: 9 | D10: 2568 | E10: 2 | F10: 0 | G10: 1 | I10: จบการศึกษา | J10: 21949 | K10: นาย | L10: กฤตภัค | M10: ศิริพัฒน์ | N10: 1101000300223 | O10: 21949
A11: มัธยมต้น | B11: ม.3 | C11: 10 | D11: 2568 | E11: 2 | F11: 0 | G11: 1 | I11: จบการศึกษา | J11: 21989 | K11: นาย | L11: กิรติ | M11: ไหมนิคม | N11: 1104200753917 | O11: 21989
A12: มัธยมต้น | B12: ม.3 | C12: 11 | D12: 2568 | E12: 2 | F12: 0 | G12: 1 | I12: จบการศึกษา | J12: 22029 | K12: เด็กชาย | L12: กานต์ธณัฏฐ์ | M12: อนันต์เวทยานนท์ | N12: 1100401552851 | O12: 22029
A13: มัธยมต้น | B13: ม.3 | C13: 12 | D13: 2568 | E13: 2 | F13: 0 | G13: 1 | I13: จบการศึกษา | J13: 22063 | K13: นาย | L13: ชนาธิป | M13: ศรีละพันธ์ | N13: 1101000276471 | O13: 22063
... A444: มัธยมต้น | B444: ม.3 | C444: 2 | D444: 2568 | E444: 2 | F444: 0 | G444: 40 | I444: จบการศึกษา | J444: 23547 | K444: นางสาว | L444: ดาวิกา | M444: ชูทับทิม | N444: 1104200782372 | O444: 23547

Sheet ม.4
A1: โรงเรียนเตรียมอุดมศึกษาพัฒนาการ ปทุมธานี
A2: รายชื่อนักเรียน ปีการศึกษา 2569 ภาคเรียนที่ 1 ชั้น ม. 4 ห้องที่ 1
A3: แผนการเรียนวิทยาศาสตร์สำหรับวิศวกรรมศาสตร์ คณะพัฒนาไทย (สีเขียว)
A4: วิชา..............................................................
A5: ครูที่ปรึกษา : 1.นายกิตติพงศ์ คุณกัณหา 2.นายเจตนิพัทธ์ ดีเป็นแก้ว
A6: ที่ | B6: เลขประจำตัว | C6: ชื่อ นามสกุล
A7: 1 | B7: 21882 | C7: นายปิยะพัฒน์ รัตติมาสกล
A8: 2 | B8: 21918 | C8: นายภานุพงศ์ เอื้ออารีย์
A9: 3 | B9: 22030 | C9: นายจิรพิพรรธ มาตคำมี
A10: 4 | B10: 22031 | C10: นายชยางกูร โฆสิต
A11: 5 | B11: 22036 | C11: นายธนกร คณาเตชวรรณ
A12: 6 | B12: 22065 | C12: นายณ นานะ มะอยู่เที่ยง
A13: 7 | B13: 22249 | C13: นายฉันทวิชญ์ หมัดลัง
A14: 8 | B14: 24080 | C14: นายณภัทธ วรโพธิ์ดก
A15: 9 | B15: 24081 | C15: นายณัฐภัทร บุตรงาม | J15: ขาด ปพ.1
A16: 10 | B16: 24082 | C16: นายทิฐินันท์ ผิวบาง | J16: ขาด ปพ.1
A17: 11 | B17: 24083 | C17: นายนราวิชญ์ ทิพย์เจริญ | J17: ขาด ปพ.1
A18: 12 | B18: 24084 | C18: นายนำโชค รัตนกร | J18: ขาด ปพ.1
A19: 13 | B19: 24085 | C19: นายพัชระ พิมพา
A20: 14 | B20: 24086 | C20: นายวีรภัทร ภูศิริฤทธิ์
A21: 15 | B21: 24087 | C21: นายสุรวัศ ป๊อกบุญเรือง
A22: 16 | B22: 21655 | C22: น.ส.ชนัญธิดา งามพล | J22: ขาด ปพ.1
A23: 17 | B23: 21772 | C23: น.ส.จันทิมา สิงอูป | J23: ขาด ปพ.1
A24: 18 | B24: 21857 | C24: น.ส.พิชญาภา ปัทมดิลก | J24: ขาด ปพ.1
A25: 19 | B25: 22028 | C25: น.ส.อังคณา พุมเสน
A26: 20 | B26: 22050 | C26: น.ส.ณัฏฐณิชา กัลยา
A27: 21 | B27: 22055 | C27: น.ส.บุญญาดา ครุธไทย
A28: 22 | B28: 22062 | C28: น.ส.ศศิพิมพ์ ศรีอภัย
A29: 23 | B29: 23553 | C29: น.ส.กัลณรินทร์ โนนสละ | J29: ขาด ปพ.1
A30: 24 | B30: 24088 | C30: น.ส.ณัฐธิดา เมืองอุดม | J30: ขาด ปพ.1
A31: 25 | B31: 24089 | C31: น.ส.เปมิกา คงผ่องแผ้ว
A32: 26 | B32: 24090 | C32: น.ส.อนันตญา เล่าสกล
A33: 27 | B33: 24124 | C33: น.ส.ธัญชนก วิเศษศิริ
A34: โรงเรียนเตรียมอุดมศึกษาพัฒนาการ ปทุมธานี
A35: รายชื่อนักเรียน ปีการศึกษา 2569 ภาคเรียนที่ 1 ชั้น ม. 4 ห้องที่ 2
A36: แผนการเรียนวิทยาศาสตร์สุขภาพ คณะเทิดกษัตริย์ (สีฟ้า)
A37: วิชา..............................................................
A38: ครูที่ปรึกษา : 1.นางสาวหทัยชนก สุกรเมือง 2. นางสาวสิริมาวีร์ สิงห์สูง
A39: ที่ | B39: เลขประจำตัว | C39: ชื่อ นามสกุล
A40: 1 | B40: 22032 | C40: นายชัชดนัย สินวิรส
...

Sheet ม.5
A1: โรงเรียนเตรียมอุดมศึกษาพัฒนาการ ปทุมธานี
A2: รายชื่อนักเรียน ปีการศึกษา 2569 ภาคเรียนที่ 1 ชั้น ม. 5 ห้องที่ 1
A3: แผนการเรียนวิทยาศาสตร์สำหรับวิศวกรรมศาสตร์ คณะรักชาติ (สีแดง)
A4: วิชา..............................................................
A5: ครูที่ปรึกษา : 1.นายธวัชชัย นาธะรัตน์
A6: ที่ | B6: เลขประจำตัว | C6: ชื่อ นามสกุล
A7: 1 | B7: 21400 | C7: นายกฤติกร สังข์ทอง
A8: 2 | B8: 21455 | C8: นายยศกร สนิทกุล
A9: 3 | B9: 21475 | C9: นายปรวัฒน์ จิ๋วประเสริฐผล
A10: 4 | B10: 22855 | C10: นายธนพัฒน์ วิบูลอัด
A11: 5 | B11: 23377 | C11: นายเจตน์สฤษฏิ์ ศรีวะปะ
A12: 6 | B12: 23378 | C12: นายต้นบุญ นิงสานนท์
A13: 7 | B13: 23379 | C13: นายคณิศ ขำสวัสดิ์
A14: 8 | B14: 23380 | C14: นายรัชต์ คล่องธนาคม
A15: 9 | B15: 23381 | C15: น.ส.ศศิรัตน์ ธุระพันธ์
A16: 10 | B16: 23382 | C16: น.ส.โศภิษฐา จันทรภักดี
A17: 11 | B17: 23383 | C17: น.ส.สุพรรณษา สูนสันเทียะ
A18: 12 | B18: 23384 | C18: น.ส.อัยยาวีร์ เค็งชัยภูมิ
A20: โรงเรียนเตรียมอุดมศึกษาพัฒนาการ ปทุมธานี
A21: รายชื่อนักเรียน ปีการศึกษา 2569 ภาคเรียนที่ 1 ชั้น ม. 5 ห้องที่ 2
A22: แผนการเรียนวิทยาศาสตร์สุขภาพ คณะใฝ่คุณธรรม (สีม่วง)
A23: วิชา..............................................................
A24: ครูที่ปรึกษา : 1. นายชนาธิป ยั่งยืน
A25: ที่ | B25: เลขประจำตัว | C25: ชื่อ นามสกุล
A26: 1 | B26: 20659 | C26: นายนัทพงษ์ สมฤทธิ์
A27: 2 | B27: 21404 | C27: นายณัฐพงศ์ สรจิตต์
A28: 3 | B28: 21439 | C28: นายกันต์ธีร์ อินสองใจ
A29: 4 | B29: 21440 | C29: นายชิติพัทธ์ เกษมวัฒนา
A30: 5 | B30: 21477 | C30: นายพิชชากร พันธุ์พิทย์แพทย์
A31: 6 | B31: 21478 | C31: นายพุฒินาท เทศะศิลป์
A32: 7 | B32: 23385 | C32: นายโชติวรุตม์ ฐิตินิธิเอกรัฐ
A33: 8 | B33: 23387 | C33: นายสุรเดช ผ่องสว่าง
A34: 9 | B34: 21121 | C34: น.ส.ลลิลรัชต์ ทิพยจักรพงศ์
A35: 10 | B35: 21195 | C35: น.ส.หทัยรัตน์ นาคทะเล
A36: 11 | B36: 21349 | C36: น.ส.กัญวรา ปินโน
A37: 12 | B37: 21419 | C37: น.ส.เจสิรินยา แสงคำเฉลียง
... A65: 40 | B65: 24198 | C65: น.ส. ณัฐวรา สภานนท์
A66: โรงเรียนเตรียมอุดมศึกษาพัฒนาการ ปทุมธานี
A67: รายชื่อนักเรียน ปีการศึกษา 2569 ภาคเรียนที่ 1 ชั้น ม. 5 ห้องที่ 3
A68: แผนการเรียนวิทยาศาสตร์-คณิตศาสตร์ คณะรักชาติ (สีแดง)
...

Sheet ม.6
A1: โรงเรียนเตรียมอุดมศึกษาพัฒนาการ ปทุมธานี
A2: รายชื่อนักเรียน ปีการศึกษา 2569 ภาคเรียนที่ 1 ชั้น ม. 6ห้องที่ 1
A3: แผนการเรียนวิทยาศาสตร์สำหรับวิศวกรรมศาสตร์ คณะผดุงศาสน์ (สีเหลือง)
A4: วิชา..............................................................
A5: ครูที่ปรึกษา : 1.นายธีรพงษ์ นามวงค์ 2.นายวรรณชนะ ปรากฏผล
A6: ที่ | B6: เลขประจำตัว | C6: ชื่อ นามสกุล
A7: 1 | B7: 20606 | C7: นายกฤตเมธ ศรีอ่อน
A8: 2 | B8: 20787 | C8: นายธนากร อินทโลหิต
A9: 3 | B9: 20795 | C9: นายศิวัฒม์ เขตชมภู
A10: 4 | B10: 20833 | C10: นายภควัฒน์ คมขำ
A11: 5 | B11: 20835 | C11: นายวรพงศ์ แซ่ตั้ง
A12: 6 | B12: 20867 | C12: นายธนากร ชึขุนทด
A13: 7 | B13: 20869 | C13: นายปารเมศ รัศมี
A14: 8 | B14: 20874 | C14: นายเมธัส ภู่นภาอำพร
A15: 9 | B15: 20875 | C15: นายยศธนะ สนิทกุล
A16: 10 | B16: 20876 | C16: นายศุภกฤต กิ่งรุ้งเพชร์
A17: 11 | B17: 21594 | C17: นายธนวัฒน์ นรัญจพันธุ์
A18: 12 | B18: 22712 | C18: นายกาก้า ทัพพ์ปวีณ์
... A28: 22 | B28: 22720 | C28: น.ส.ธนพร ทิพย์คงคา
A29: โรงเรียนเตรียมอุดมศึกษาพัฒนาการ ปทุมธานี
A30: รายชื่อนักเรียน ปีการศึกษา 2569 ภาคเรียนที่ 1 ชั้น ม. 6ห้องที่ 2
A31: แผนการเรียนวิทยาศาสตร์สุขภาพ คณะเทิดกษัตริย์ (สีฟ้า)
A32: วิชา..............................................................
A33: ครูที่ปรึกษา : 1.น.ส.ณัฐชา งามลักษณ์ 2.นางสาวจิราพร นิลตีบ
A34: ที่ | B34: เลขประจำตัว | C34: ชื่อ นามสกุล
A35: 1 | B35: 20486 | C35: นายวิษณุ สุริยะ
A36: 2 | B36: 20662 | C36: นายรชต ฮวบเอี่ยม
A37: 3 | B37: 20667 | C37: นายธัชกร โรจน์พินิจนัย
A38: 4 | B38: 20827 | C38: นายธารารัชช์ ดาววงษ์
A39: 5 | B39: 20863 | C39: นายกนกพล ทองแท่ง
A40: 6 | B40: 20864 | C40: นายจิรายุ บุศย์จันทร์
A41: 7 | B41: 20865 | C41: นายญาณวุฒิ คำโฮงค์
A42: 8 | B42: 20872 | C42: นายภาวัต ประสงค์ผล
A43: 9 | B43: 20907 | C43: นายศุภกรณ์ ดอกกุหลาบ
A44: 10 | B44: 22228 | C44: นายธนากร หวังวก
A45: 11 | B45: 20498 | C45: น.ส.ณัฏฐณิชา มีชัย
A46: 12 | B46: 20511 | C46: น.ส.สุธาวี โพธิ์ทอง
... A73: 39 | B73: 22722 | C73: น.ส.เมตตา นิ่มอนงค์
A74: โรงเรียนเตรียมอุดมศึกษาพัฒนาการ ปทุมธานี
A75: รายชื่อนักเรียน ปีการศึกษา 2569 ภาคเรียนที่ 1 ชั้น ม. 6ห้องที่ 3
...

Sheet ม.668
A1: โรงเรียนเตรียมอุดมศึกษาพัฒนาการ ปทุมธานี
A2: รายชื่อนักเรียน ปีการศึกษา 2568 ภาคเรียนที่ 2 ชั้น ม. 6 ห้องที่ 1
A3: แผนการเรียนวิทยาศาสตร์สำหรับวิศวกรรมศาสตร์ คณะใฝ่คุณธรรม (สีม่วง)
A4: วิชา..............................................................
A5: ครูที่ปรึกษา : 1.นายกิตติพงศ์ คุณกัณหา 2.นายธีรพงษ์ นามวงค์
A6: ที่ | B6: เลขประจำตัว | C6: ชื่อ นามสกุล
A7: 1 | B7: 19815 | C7: นายมานิตย์ เบญจมาศ
A8: 2 | B8: 19978 | C8: นายรังสิมันตุ์ ดะแปรกะเซ็ม
A9: 3 | B9: 20064 | C9: นายศุภเจตน์สฤษฎิ์ กรบุญไตรทศ
A10: 4 | B10: 20133 | C10: นายจุติณัฏฐ์ จันทร์ภักดิ์
A11: 5 | B11: 20137 | C11: นายธนาพัฒน์ หาแก้ว
A12: 6 | B12: 20142 | C12: นายภัทรชัย ไทยภักดี
A13: 7 | B13: 20178 | C13: นายถิรศักดิ์ อรรคชาติ
A14: 8 | B14: 20180 | C14: นายบุฌยกร โกมลสิรีหิรัญ
A15: 9 | B15: 20182 | C15: นายปรีดี ราชฉวาง
A16: 10 | B16: 20184 | C16: นายพลกฤต สุทธิรักษ์
A17: 11 | B17: 20185 | C17: นายพีรภาสร์ เชษฐปริญญา
A18: 12 | B18: 20186 | C18: นายภูริวิชช์ สุภา
... A37: 31 | B37: 22092 | C37: น.ส.จินตนา กุลมา
A38: 32 | B38: 22093 | C38: น.ส.เพชราภรณ์ ระวิงทอง | L38: น.ส.ธนพร ระวิงทอง
A39: 33 | B39: 22094 | C39: น.ส.สุมณฑา แดงเครือ
A40: 34 | B40: 22095 | C40: น.ส.โสรวัลย์ ทาเงิน
A41: โรงเรียนเตรียมอุดมศึกษาพัฒนาการ ปทุมธานี
A42: รายชื่อนักเรียน ปีการศึกษา 2568 ภาคเรียนที่ 2 ชั้น ม. 6 ห้องที่ 2
A43: แผนการเรียนวิทยาศาสตร์-คณิตศาสตร์ คณะพัฒนาไทย (สีเขียว)
A44: วิชา..............................................................
A45: ครูที่ปรึกษา : 1. นางสาวณัฐธิดา เยาวลักษณ์โยธิน
A46: ที่ | B46: เลขประจำตัว | C46: ชื่อ นามสกุล
A47: 1 | B47: 19932 | C47: นายคุณภัคร คุ้มบาง
A48: 2 | B48: 20061 | C48: นายภควัต รัตนานิติกุล
A49: 3 | B49: 20066 | C49: นายอภิชาติ นันท์บุญมา
A50: 4 | B50: 20092 | C50: นายจีรภัทร จิตรดี
A51: 5 | B51: 20095 | C51: นายณัฐภัทร สืบสาร
A52: 6 | B52: 20132 | C52: นายจิรภาส เจริญศิริ
A53: 7 | B53: 20146 | C53: นายสิรภัทร ทองประดับ
A54: 8 | B54: 20147 | C54: นายสุธีมนต์ คุ้มฤทธิ์
A55: 9 | B55: 22096 | C55: นายจิรสิน จงเทียมเท่า
A56: 10 | B56: 23562 | C56: นายธนกฤต เทียมเศวต
A57: 11 | B57: 19834 | C57: น.ส.ปาวิดา รอบเขตรัมย์
A58: 12 | B58: 19949 | C58: น.ส.กุลณัฐ กาญจนาธรรมรัฐ
...

Sheet ม.3เดิม
A1: โรงเรียนเตรียมอุดมศึกษาพัฒนาการ ปทุมธานี
B2: รายชื่อนักเรียน ปีการศึกษา 2565 ภาคเรียนที่ 2 ชั้น ม. 3 ห้องที่ 1 คณะใฝ่คุณธรรม (สีม่วง)
A3: วิชา..............................................................
A4: ครูที่ปรึกษา : 1.นางสาวลดาวัลย์ ดวงจิตร 2. นางสาวกรชนก มูละผลารักษ์
A5: ที่ | B5: เลขประจำตัว | C5: ชื่อ นามสกุล
A6: 1 | B6: 19764 | C6: ด.ช.โกวิทย์ นิลาคัมม์
A7: 2 | B7: 19765 | C7: ด.ช.ญาณวุฒิ ทับทองคำ
A8: 3 | B8: 19767 | C8: ด.ช.ธนพล สีสังข์
A9: 4 | B9: 19768 | C9: ด.ช.ธีรเดช โพธิ์เตี้ย
A10: 5 | B10: 19770 | C10: ด.ช.เนติธร รอดรัศมี​
A11: 6 | B11: 19773 | C11: ด.ช.เมธัส ศรีละโคตร
A12: 7 | B12: 19774 | C12: ด.ช.รชานนท์ มะนาวหวาน
A13: 8 | B13: 19775 | C13: ด.ช.วงศธร ภูพวก
A14: 9 | B14: 19776 | C14: ด.ช.วทัญญู อยู่สุข
A15: 10 | B15: 19777 | C15: ด.ช.วราพล ไขแสง
A16: 11 | B16: 19778 | C16: ด.ช.วัชรพงศ์ จังโส
A17: 12 | B17: 19779 | C17: ด.ช.เวชพิสิฐ สงวนศรี
... A44: 39 | B44: 21596 | C44: ด.ญ.จารุวรรณ สะทองแก้ว
B45: โรงเรียนเตรียมอุดมศึกษาพัฒนาการ ปทุมธานี
B46: รายชื่อนักเรียน ปีการศึกษา 2565 ภาคเรียนที่ 2 ชั้น ม. 3 ห้องที่ 2 คณะผดุงศาสน์ (สีเหลือง)
A47: วิชา..............................................................
A48: ครูที่ปรึกษา : 1.นางสาวกัลยา วิทยาศิริกุล 2. นางสาวกรรณิการ์ นันบุญมา
A49: ที่ | B49: เลขประจำตัว | C49: ชื่อ นามสกุล
A50: 1 | B50: 19804 | C50: ด.ช.จิระศักดิ์ เนาวราช
A51: 2 | B51: 19805 | C51: ด.ช.ชยังกูร นาคงาม
A52: 3 | B52: 19806 | C52: ด.ช.ธราเทพ กิตติประมวกุล
A53: 4 | B53: 19807 | C53: ด.ช.ธีรภัทร นามวงษ์
A54: 5 | B54: 19808 | C54: ด.ช.ธีรภัทร วงษาลี
A55: 6 | B55: 19809 | C55: ด.ช.ธีรภาพ กรีสง่า
A56: 7 | B56: 19810 | C56: ด.ช.ธีรศักดิ์ มีกุล
A57: 8 | B57: 19811 | C57: ด.ช.นพรัตน์ สิริกานนท์
A58: 9 | B58: 19812 | C58: ด.ช.พงศกร สายมงคล
A59: 10 | B59: 19813 | C59: ด.ช.พีรพัฒน์ เฒอรัมย์
A60: 11 | B60: 19814 | C60: ด.ช.ภัทรายุทธ ประพลรัตนัง
A61: 12 | B61: 19815 | C61: ด.ช.มานิตย์ เบญจมาศ
... A91: 42 | B91: 20429 | C91: ด.ญ.ภัทร์นรินทร์ ผลัญชัย
B92: โรงเรียนเตรียมอุดมศึกษาพัฒนาการ ปทุมธานี
B93: รายชื่อนักเรียน ปีการศึกษา 2565 ภาคเรียนที่ 2 ชั้น ม. 3 ห้องที่ 3 คณะรักชาติ (สีแดง)
A94: วิชา..............................................................
A95: ครูที่ปรึกษา : 1.นายมานัส เดชไชย 2. นางสาวนิชาภัทร หอมทอง
...

Sheet 1.+GPA-PR--2563_2-3- (1)
A1: เลขประจำตัวประชาชน | B1: คำนำหน้าชื่อ | C1: ชื่อ | D1: นามสกุล | F1: รหัสนักเรียน | G1: GPA | H1: GPA 70% | I1: ONET 30% | J1: GPAX | K1: PR | L1: ท. เรียน | M1: ท. ได้ | N1: ท. เฉลี่ย | O1: ค. เรียน | P1: ค. ได้ | Q1: ค. เฉลี่ย | R1: ว. เรียน | S1: ว. ได้ | T1: ว. เฉลี่ย | U1: ส. เรียน | V1: ส. ได้ | W1: ส. เฉลี่ย | X1: พ. เรียน | Y1: พ. ได้ | Z1: พ. เฉลี่ย | AA1: ศ. เรียน | AB1: ศ. ได้ | AC1: ศ. เฉลี่ย | AD1: ง. เรียน | AE1: ง. ได้ | AF1: ง. เฉลี่ย | AG1: อ. เรียน | AH1: อ. ได้ | AI1: อ. เฉลี่ย | AJ1: ชื่อ-นามสกุลบิดา | AK1: ชื่อ-นามสกุลมารดา | AL1: วันเกิดนักเรียน | AM1: ปีการศึกษา | AN1: ภาคเรียนที่ | AO1: ชั้น/ห้อง | AP1: เลขที่ | AQ1: อันดับที่ของห้อง | AR1: จำนวนนักเรียนทั้งห้อง | AS1: อันดับที่ของระดับ | AT1: จำนวนนักเรียนทั้งระดับ | AU1: วันที่จบการศึกษา | AV1: วันที่ออกจากโรงเรียน | AW1: เหตุที่ออก | AX1: ONET_1 | AY1: ONET_2 | AZ1: ONET_3 | BA1: ONET_4 | BB1: ONET_8 | BC1: คุณลักษณะ | BD1: อ่าน คิด วิเคราะห์ | BE1: กิจกรรม | BF1: โรงเรียนเดิม | BG1: จังหวัด
A2: 1-1005-01650-22-6 | B2: นาย | C2: กิตติชัย | D2: เครือสิงห์ | E2: กิตติชัย เครือสิงห์ | F2: 18016 | G2: 1.33 | K2: 99.38 | L2: 11 | M2: 11 | N2: 1.15 | O2: 13 | P2: 13 | Q2: 1.21 | R2: 12 | S2: 12 | T2: 1.1 | U2: 15 | V2: 15 | W2: 1.2 | X2: 6 | Y2: 6 | Z2: 1.58 | AA2: 6 | AB2: 6 | AC2: 1.62 | AD2: 9 | AE2: 9 | AF2: 1.91 | AG2: 10 | AH2: 10 | AI2: 1.07 | AJ2: นายประเสริฐ บทนอก | AK2: นางสาวกมลวรรณ เครือสิงห์ | AL2: 236589 | AM2: 2563 | AN2: 2 | AO2: ม.3/2 | AP2: 1 | AQ2: 1 | AR2: 32 | AS2: 1 | AT2: 404 | AU2: 242657 | AV2: 242657 | AW2: จบการศึกษาภาคบังคับ | BC2: ดี | BD2: ดี | BE2: ผ่าน | BF2: พระวิสุทธิวงส์ | BG2: ปทุมธานี
A3: 1-1037-03906-97-6 | B3: นาย | C3: อนรรฆ | D3: ยิ้มน้อย | E3: อนรรฆ ยิ้มน้อย | F3: 18085 | G3: 1.8 | I3: 0.49 | J3: 1.75 | K3: 99.88 | L3: 10 | M3: 10 | N3: 1.87 | O3: 11 | P3: 11 | Q3: 1.13 | R3: 10.5 | S3: 10.5 | T3: 1.5 | U3: 15 | V3: 15 | W3: 1.86 | X3: 6 | Y3: 6 | Z3: 2.54 | AA3: 6 | AB3: 6 | AC3: 2.41 | AD3: 9.5 | AE3: 9.5 | AF3: 2.1 | AG3: 11 | AH3: 11 | AI3: 1.43 | AJ3: นายอำพลศักดิ์ ยิ้มน้อย | AK3: นางอริศรา ผกายธรรม | AL3: 236685 | AM3: 2563 | AN3: 2 | AO3: ม.3/2 | AP3: 2 | AQ3: 1 | AR3: 32 | AS3: 1 | AT3: 404 | AU3: 242622 | AV3: 242622 | AW3: จบการศึกษาภาคบังคับ | AX3: 38 | AY3: 24 | AZ3: 22 | BB3: 34 | BC3: ดี | BD3: ดี | BE3: ผ่าน | BF3: วัดสามง่าม | BG3: กรุงเทพมหานคร
A4: 1-1394-00010-31-9 | B4: นาย | C4: ธันวา | D4: พุฒสุภาพ | E4: ธันวา พุฒสุภาพ | F4: 18209 | G4: 1.55 | I4: 0.53 | J4: 1.61 | K4: 99.63 | L4: 9 | M4: 9 | N4: 1.58 | O4: 14 | P4: 14 | Q4: 1.19 | R4: 10.5 | S4: 10.5 | T4: 1.3 | U4: 15 | V4: 15 | W4: 1.25 | X4: 6 | Y4: 6 | Z4: 2.12 | AA4: 6 | AB4: 6 | AC4: 1.87 | AD4: 5 | AE4: 5 | AF4: 2.3 | AG4: 14.5 | AH4: 14.5 | AI4: 1.55 | AJ4: นายสุวรรณ์ พุฒสุภาพ | AK4: นางสาวนิรันดร ศรีสถาน | AL4: 236659 | AM4: 2563 | AN4: 2 | AO4: ม.3/5 | AP4: 1 | AQ4: 1 | AR4: 37 | AS4: 1 | AT4: 404 | AU4: 242657 | AV4: 242657 | AW4: จบการศึกษาภาคบังคับ | AX4: 42 | AY4: 20 | AZ4: 30.5 | BB4: 36 | BC4: ดี | BD4: ดี | BE4: ผ่าน | BF4: วัดเสมียนนารี | BG4: กรุงเทพมหานคร
A5: 1-1007-03704-74-2 | B5: นาย | C5: ชยุตพล | D5: สำลีขาว | E5: ชยุตพล สำลีขาว | F5: 18298 | G5: 1.86 | K5: 99.38 | L5: 9 | M5: 9 | N5: 1.75 | O5: 14 | P5: 14 | Q5: 1.21 | R5: 16.5 | S5: 16.5 | T5: 1.63 | U5: 15 | V5: 15 | W5: 1.98 | X5: 6 | Y5: 6 | Z5: 2.83 | AA5: 6 | AB5: 6 | AC5: 2.79 | AD5: 5 | AE5: 5 | AF5: 2.5 | AG5: 10 | AH5: 10 | AI5: 1.82 | AJ5: นายผดุง สำลีขาว | AK5: นางอำไพ สำลีขาว | AL5: 236731 | AM5: 2563 | AN5: 2 | AO5: ม.3/7 | AP5: 1 | AQ5: 1 | AR5: 39 | AS5: 1 | AT5: 404 | AU5: 242657 | AV5: 242657 | AW5: จบการศึกษาภาคบังคับ | BC5: ดีเยี่ยม | BD5: ดี | BE5: ผ่าน | BF5: วัดคลองชัน | BG5: ปทุมธานี
A6: 1-4999-00441-10-3 | B6: นาย | C6: กฤษกร | D6: แซ่เฮ้ง | E6: กฤษกร แซ่เฮ้ง | F6: 18612 | G6: 1.79 | K6: 99.38 | L6: 11 | M6: 11 | N6: 1.27 | O6: 15 | P6: 15 | Q6: 1.18 | R6: 15 | S6: 15 | T6: 1.61 | U6: 15 | V6: 15 | W6: 1.75 | X6: 6 | Y6: 6 | Z6: 1.7 | AA6: 6 | AB6: 6 | AC6: 2.25 | AD6: 8.5 | AE6: 8.5 | AF6: 1.7 | AG6: 9 | AH6: 9 | AI6: 3.58 | AJ6: นายสมบูรณ์ แซ่เฮ้ง | AK6: นางสาววธิดา สุวรรณทอง | AL6: 236530 | AM6: 2563 | AN6: 2 | AO6: ม.3/1 | AP6: 1 | AQ6: 1 | AR6: 35 | AS6: 1 | AT6: 404 | AU6: 242657 | AV6: 242657 | AW6: จบการศึกษาภาคบังคับ | BC6: ดีเยี่ยม | BD6: ดี | BE6: ผ่าน | BF6: วงศ์ไพฑูรย์ | BG6: ปทุมธานี
A7: 1-1042-00479-91-2 | B7: นาย | C7: กันต์กวี | D7: แถมมุลตรี | E7: กันต์กวี แถมมุลตรี | F7: 18613 | G7: 2.78 | K7: 99.38 | L7: 11 | M7: 11 | N7: 2.72 | O7: 15 | P7: 15 | Q7: 2.13 | R7: 15 | S7: 15 | T7: 3.03 | U7: 15 | V7: 15 | W7: 3.05 | X7: 6 | Y7: 6 | Z7: 2.91 | AA7: 6 | AB7: 6 | AC7: 3.2 | AD7: 8.5 | AE7: 8.5 | AF7: 2.97 | AG7: 9 | AH7: 9 | AI7: 2.58 | AJ7: นายสุดใจ แถมมุลตรี | AK7: นางจันทร์จิรา ไกรประสิทธิ์ | AL7: 236932 | AM7: 2563 | AN7: 2 | AO7: ม.3/1 | AP7: 2 | AQ7: 1 | AR7: 35 | AS7: 1 | AT7: 404 | AU7: 242622 | AV7: 242622 | AW7: จบการศึกษาภาคบังคับ | BC7: ดีเยี่ยม | BD7: ดีเยี่ยม | BE7: ผ่าน | BF7: วัดราษฎร์ศรัทธาราม | BG7: ปทุมธานี
A8: 1-1397-00049-23-7 | B8: นาย | C8: กิตติพัศ | D8: อนันตกูล | E8: กิตติพัศ อนันตกูล | F8: 18615 | G8: 2.07 | K8: 99.38 | L8: 11 | M8: 11 | N8: 1.97 | O8: 15 | P8: 15 | Q8: 1.53 | R8: 15 | S8: 15 | T8: 2.18 | U8: 15 | V8: 15 | W8: 2.31 | X8: 6 | Y8: 6 | Z8: 2.37 | AA8: 6 | AB8: 6 | AC8: 2.83 | AD8: 8.5 | AE8: 8.5 | AF8: 2.17 | AG8: 9 | AH8: 9 | AI8: 1.41 | AJ8: นายคมกฤษ อนันตกูล | AK8: นางกานต์พิชชา แก้วฉาย | AL8: 237050 | AM8: 2563 | AN8: 2 | AO8: ม.3/1 | AP8: 3 | AQ8: 1 | AR8: 35 | AS8: 1 | AT8: 404 | AU8: 242622 | AV8: 242622 | AW8: จบการศึกษาภาคบังคับ | BC8: ดีเยี่ยม | BD8: ดี | BE8: ผ่าน | BF8: วัดราษฎร์ศรัทธาราม | BG8: ปทุมธานี
A9: 1-6799-00665-07-7 | B9: เด็กชาย | C9: จิตติพัฒน์ | D9: ทะสะภาค | E9: จิตติพัฒน์ ทะสะภาค | F9: 18616 | G9: 3.05 | K9: 99.38 | L9: 11 | M9: 11 | N9: 3.34 | O9: 15 | P9: 15 | Q9: 2.55 | R9: 15 | S9: 15 | T9: 2.85 | U9: 15 | V9: 15 | W9: 3.18 | X9: 6 | Y9: 6 | Z9: 3.16 | AA9: 6 | AB9: 6 | AC9: 3.5 | AD9: 8.5 | AE9: 8.5 | AF9: 3.44 | AG9: 9 | AH9: 9 | AI9: 2.75 | AJ9: นายสายันห์ ทะสะภาค | AK9: นางสาวจารุณี สอนศิริ | AL9: 237131 | AM9: 2563 | AN9: 2 | AO9: ม.3/1 | AP9: 4 | AQ9: 1 | AR9: 35 | AS9: 1 | AT9: 404 | AU9: 242622 | AV9: 242622 | AW9: จบการศึกษาภาคบังคับ | BC9: ดีเยี่ยม | BD9: ดีเยี่ยม | BE9: ผ่าน | BF9: วัดราษฎร์ศรัทธาราม | BG9: ปทุมธานี
A10: 1-1037-04054-32-9 | B10: นาย | C10: จิรภาส | D10: แก้วฉลาด | E10: จิรภาส แก้วฉลาด | F10: 18617 | G10: 2.61 | K10: 99.38 | L10: 11 | M10: 11 | N10: 2.15 | O10: 15 | P10: 15 | Q10: 2.35 | R10: 15 | S10: 15 | T10: 2.61 | U10: 15 | V10: 15 | W10: 2.6 | X10: 6 | Y10: 6 | Z10: 2.7 | AA10: 6 | AB10: 6 | AC10: 3.25 | AD10: 8.5 | AE10: 8.5 | AF10: 2.64 | AG10: 9 | AH10: 9 | AI10: 3 | AJ10: นายประภาส แก้วฉลาด | AK10: นางสาวลำไพพอน ไมคำ | AL10: 237038 | AM10: 2563 | AN10: 2 | AO10: ม.3/1 | AP10: 5 | AQ10: 1 | AR10: 35 | AS10: 1 | AT10: 404 | AU10: 242622 | AV10: 242622 | AW10: จบการศึกษาภาคบังคับ | BC10: ดีเยี่ยม | BD10: ดีเยี่ยม | BE10: ผ่าน | BF10: เตรียมบัณฑิต(บริบูรณ์ศิลป์ศึกษา) | BG10: ปทุมธานี
A11: 1-1389-00021-44-1 | B11: นาย | C11: เจษฎา | D11: ฝอยลามลวด | E11: เจษฎา ฝอยลามลวด | F11: 18618 | G11: 2.3 | K11: 99.38 | L11: 11 | M11: 11 | N11: 2.11 | O11: 15 | P11: 15 | Q11: 1.95 | R11: 15 | S11: 15 | T11: 2.4 | U11: 15 | V11: 15 | W11: 2.21 | X11: 6 | Y11: 6 | Z11: 2.29 | AA11: 6 | AB11: 6 | AC11: 2.79 | AD11: 8.5 | AE11: 8.5 | AF11: 2.26 | AG11: 9 | AH11: 9 | AI11: 2.83 | AJ11: นายกระจ่าง ฝอยลามลวด | AK11: นางปัทมา ฝอยลามลวด | AL11: 237029 | AM11: 2563 | AN11: 2 | AO11: ม.3/1 | AP11: 6 | AQ11: 1 | AR11: 35 | AS11: 1 | AT11: 404 | AU11: 242622 | AV11: 242622 | AW11: จบการศึกษาภาคบังคับ | BC11: ดีเยี่ยม | BD11: ดี | BE11: ผ่าน | BF11: วัดเกตุประภา | BG11: ปทุมธานี
A12: 1-1020-03754-75-7 | B12: นาย | C12: ชยางกูร | D12: ม่วงจีน | E12: ชยางกูร ม่วงจีน | F12: 18619 | G12: 2.92 | K12: 99.38 | L12: 11 | M12: 11 | N12: 3.02 | O12: 15 | P12: 15 | Q12: 2.6 | R12: 15 | S12: 15 | T12: 2.98 | U12: 15 | V12: 15 | W12: 2.85 | X12: 6 | Y12: 6 | Z12: 3.16 | AA12: 6 | AB12: 6 | AC12: 3.29 | AD12: 8.5 | AE12: 8.5 | AF12: 3.23 | AG12: 9 | AH12: 9 | AI12: 2.58 | AJ12: นายณัฐพร ม่วงจีน | AK12: นางสาวกฤศฎา เอี่ยมสะอาด | AL12: 237073 | AM12: 2563 | AN12: 2 | AO12: ม.3/1 | AP12: 7 | AQ12: 1 | AR12: 35 | AS12: 1 | AT12: 404 | AU12: 242622 | AV12: 242622 | AW12: จบการศึกษาภาคบังคับ | BC12: ดีเยี่ยม | BD12: ดีเยี่ยม | BE12: ผ่าน | BF12: วัดคลองชัน | BG12: ปทุมธานี
A13: 1-6699-00556-62-6 | B13: นาย | C13: ชัยนันท์ | D13: ศรีโสดา | E13: ชัยนันท์ ศรีโสดา | F13: 18620 | G13: 1.93 | K13: 99.38 | L13: 11 | M13: 11 | N13: 1.4 | O13: 15 | P13: 15 | Q13: 2.08 | R13: 15 | S13: 15 | T13: 2.15 | U13: 15 | V13: 15 | W13: 1.81 | X13: 6 | Y13: 6 | Z13: 1.91 | AA13: 6 | AB13: 6 | AC13: 2.41 | AD13: 8.5 | AE13: 8.5 | AF13: 1.88 | AG13: 9 | AH13: 9 | AI13: 1.58 | AJ13: นายแวว ศรีโสดา | AK13: นางสาวสาคร คุมสุข | AL13: 236919 | AM13: 2563 | AN13: 2 | AO13: ม.3/1 | AP13: 8 | AQ13: 1 | AR13: 35 | AS13: 1 | AT13: 404 | AU13: 242622 | AV13: 242622 | AW13: จบการศึกษาภาคบังคับ | BC13: ดีเยี่ยม | BD13: ดี | BE13: ผ่าน | BF13: วัดสุวรรณ | BG13: ปทุมธานี
A14: 1-1397-00047-83-8 | B14: นาย | C14: ฐปนวัฒน์ | D14: ก๋าอิน | E14: ฐปนวัฒน์ ก๋าอิน | F14: 18621 | G14: 1.88 | K14: 99.38 | L14: 11 | M14: 11 | N14: 2.09 | O14: 15 | P14: 15 | Q14: 1.31 | R14: 15 | S14: 15 | T14: 1.88 | U14: 15 | V14: 15 | W14: 2.06 | X14: 6 | Y14: 6 | Z14: 2.37 | AA14: 6 | AB14: 6 | AC14: 2.33 | AD14: 8.5 | AE14: 8.5 | AF14: 1.88 | AG14: 9 | AH14: 9 | AI14: 1.25 | AJ14: นายวิทยา ก๋าอิน | AK14: นางอุบลลักษณ์ ก๋าอิน | AL14: 237004 | AM14: 2563 | AN14: 2 | AO14: ม.3/1 | AP14: 9 | AQ14: 1 | AR14: 35 | AS14: 1 | AT14: 404 | AU14: 242657 | AV14: 242657 | AW14: จบการศึกษาภาคบังคับ | BC14: ดีเยี่ยม | BD14: ดี | BE14: ผ่าน | BF14: ผ่องสุวรรณวิทยา | BG14: ปทุมธานี
A15: 1-1004-01307-47-3 | B15: นาย | C15: ฐพันธ์ปภพ | D15: ลับสันเทียะ | E15: ฐพันธ์ปภพ ลับสันเทียะ | F15: 18622 | G15: 2.08 | K15: 99.38 | L15: 11 | M15: 11 | N15: 1.47 | O15: 15 | P15: 15 | Q15: 2.85 | R15: 15 | S15: 15 | T15: 2.01 | U15: 15 | V15: 15 | W15: 1.8 | X15: 6 | Y15: 6 | Z15: 2.45 | AA15: 6 | AB15: 6 | AC15: 2.75 | AD15: 8.5 | AE15: 8.5 | AF15: 1.91 | AG15: 9 | AH15: 9 | AI15: 1.5 | AJ15: นายสมศักดิ์ ลับสันเทียะ | AK15: นางสาวอรศรี หนูเจ้ย | AL15: 237046 | AM15: 2563 | AN15: 2 | AO15: ม.3/1 | AP15: 10 | AQ15: 1 | AR15: 35 | AS15: 1 | AT15: 404 | AU15: 242622 | AV15: 242622 | AW15: จบการศึกษาภาคบังคับ | BC15: ดีเยี่ยม | BD15: ดี | BE15: ผ่าน | BF15: สหราษฏร์บำรุง | BG15: ปทุมธานี
A16: 1-1389-00019-08-0 | B16: นาย | C16: ณภัทร | D16: แฟงสุวรรณ | E16: ณภัทร แฟงสุวรรณ | F16: 18623 | G16: 1.29 | K16: 99.38 | L16: 11 | M16: 9.5 | N16: 1.31 | O16: 15 | P16: 5 | Q16: 0.46 | R16: 15 | S16: 10 | T16: 1.16 | U16: 15 | V16: 13 | W16: 1.66 | X16: 6 | Y16: 5.5 | Z16: 2.08 | AA16: 6 | AB16: 4.5 | AC16: 1.62 | AD16: 7.5 | AE16: 7.5 | AF16: 1.6 | AG16: 9 | AH16: 7.5 | AI16: 0.91 | AJ16: นายไพศาล แฟงสุวรรณ | AK16: นางสาวเสาวลักษณ์ บุญช่วย | AL16: 236850 | AM16: 2563 | AN16: 2 | AO16: ม.3/1 | AP16: 11 | AQ16: 1 | AR16: 35 | AS16: 1 | AT16: 404 | BC16: ดี | BD16: ดี | BE16: ผ่าน | BF16: วัดธัญญะผล | BG16: ปทุมธานี
A17: 1-1043-00944-88-9 | B17: เด็กชาย | C17: ณัฏฐนันท์ | D17: อุทัยพจน์ | E17: ณัฏฐนันท์ อุทัยพจน์ | F17: 18624 | G17: 1.96 | K17: 99.38 | L17: 11 | M17: 11 | N17: 1.4 | O17: 15 | P17: 15 | Q17: 1.4 | R17: 15 | S17: 15 | T17: 2.06 | U17: 15 | V17: 15 | W17: 2.3 | X17: 6 | Y17: 6 | Z17: 2.33 | AA17: 6 | AB17: 6 | AC17: 2.66 | AD17: 8.5 | AE17: 8.5 | AF17: 2.41 | AG17: 9 | AH17: 9 | AI17: 1.5 | AJ17: นายมงคล อุทัยพจน์ | AK17: นางยศวรรธน์ อุทัยพจน์ | AL17: 237221 | AM17: 2563 | AN17: 2 | AO17: ม.3/1 | AP17: 12 | AQ17: 1 | AR17: 35 | AS17: 1 | AT17: 404 | AU17: 242622 | AV17: 242622 | AW17: จบการศึกษาภาคบังคับ | BC17: ดีเยี่ยม | BD17: ดี | BE17: ผ่าน | BF17: พระวิสุทธิวงส์ | BG17: ปทุมธานี
A18: 1-1037-04095-58-1 | B18: เด็กชาย | C18: ธนบดี | D18: เบ๊ยัง | E18: ธนบดี เบ๊ยัง | F18: 18625 | G18: 2.01 | K18: 99.38 | L18: 11 | M18: 11 | N18: 1.63 | O18: 15 | P18: 15 | Q18: 1.83 | R18: 15 | S18: 15 | T18: 1.88 | U18: 15 | V18: 15 | W18: 2.3 | X18: 6 | Y18: 6 | Z18: 2.37 | AA18: 6 | AB18: 6 | AC18: 2.83 | AD18: 8.5 | AE18: 8.5 | AF18: 1.82 | AG18: 9 | AH18: 9 | AI18: 1.75 | AJ18: นายภคพล เบ๊ยัง | AK18: นางสาวภคมน การวิธี | AL18: 237201 | AM18: 2563 | AN18: 2 | AO18: ม.3/1 | AP18: 13 | AQ18: 1 | AR18: 35 | AS18: 1 | AT18: 404 | AU18: 242622 | AV18: 242622 | AW18: จบการศึกษาภาคบังคับ | BC18: ดีเยี่ยม | BD18: ดี | BE18: ผ่าน | BF18: จินดานุกูล | BG18: กรุงเทพมหานคร
A19: 1-1042-00519-15-9 | B19: เด็กชาย | C19: ธนพล | D19: แจ่มจำรัส | E19: ธนพล แจ่มจำรัส | F19: 18626 | G19: 2.16 | K19: 99.38 | L19: 11 | M19: 11 | N19: 1.93 | O19: 15 | P19: 15 | Q19: 2.21 | R19: 15 | S19: 15 | T19: 2.16 | U19: 15 | V19: 15 | W19: 2.31 | X19: 6 | Y19: 6 | Z19: 2.2 | AA19: 6 | AB19: 6 | AC19: 2.62 | AD19: 8.5 | AE19: 8.5 | AF19: 2.14 | AG19: 9 | AH19: 9 | AI19: 1.83 | AJ19: นายธีระ แจ่มจำรัส | AK19: นางสาววิลัยพร ขำสอาด | AL19: 237172 | AM19: 2563 | AN19: 2 | AO19: ม.3/1 | AP19: 14 | AQ19: 1 | AR19: 35 | AS19: 1 | AT19: 404 | AU19: 242622 | AV19: 242622 | AW19: จบการศึกษาภาคบังคับ | BC19: ดีเยี่ยม | BD19: ดี | BE19: ผ่าน | BF19: ปิยวัฒนศาสตร์ | BG19: ปทุมธานี
A20: 1-1389-00019-67-5 | B20: นาย | C20: ธนัตถ์ | D20: เล็กน้อยวงค์ | E20: ธนัตถ์ เล็กน้อยวงค์ | F20: 18627 | G20: 1.42 | K20: 99.38 | L20: 11 | M20: 11 | N20: 1.2 | O20: 15 | P20: 15 | Q20: 1.05 | R20: 15 | S20: 15 | T20: 1.43 | U20: 15 | V20: 15 | W20: 1.5 | X20: 6 | Y20: 6 | Z20: 1.79 | AA20: 6 | AB20: 6 | AC20: 1.83 | AD20: 8.5 | AE20: 8.5 | AF20: 1.47 | AG20: 9 | AH20: 9 | AI20: 1.16 | AJ20: นายธีระศักดิ์ รักธรรม | AK20: นางสาวพรทิพย์ เล็กน้อยวงค์ | AL20: 236898 | AM20: 2563 | AN20: 2 | AO20: ม.3/1 | AP20: 15 | AQ20: 1 | AR20: 35 | AS20: 1 | AT20: 404 | AU20: 242657 | AV20: 242657 | AW20: จบการศึกษาภาคบังคับ | BC20: ดี | BD20: ดี | BE20: ผ่าน | BF20: เจริญดีวิทยา | BG20: ปทุมธานี
A21: 1-1005-01654-68-0 | B21: นาย | C21: ปวริศ | D21: เปรมภักตร์ | E21: ปวริศ เปรมภักตร์ | F21: 18630 | G21: 3.23 | K21: 99.38 | L21: 11 | M21: 11 | N21: 3.47 | O21: 15 | P21: 15 | Q21: 2.76 | R21: 15 | S21: 15 | T21: 3.41 | U21: 15 | V21: 15 | W21: 3.43 | X21: 6 | Y21: 6 | Z21: 3.25 | AA21: 6 | AB21: 6 | AC21: 3.45 | AD21: 8.5 | AE21: 8.5 | AF21: 3 | AG21: 9 | AH21: 9 | AI21: 3.08 | AJ21: นายฐานพัฒน์ เปรมภักตร์ | AK21: นางสาวปรัตน์ดา สุรทรวาทิน | AL21: 236740 | AM21: 2563 | AN21: 2 | AO21: ม.3/1 | AP21: 16 | AQ21: 1 | AR21: 35 | AS21: 1 | AT21: 404 | AU21: 242622 | AV21: 242622 | AW21: จบการศึกษาภาคบังคับ | BC21: ดีเยี่ยม | BD21: ดีเยี่ยม | BE21: ผ่าน | BF21: โสมาภาพัฒนา | BG21: กรุงเทพมหานคร
A22: 1-1299-01982-94-1 | B22: เด็กชาย | C22: พัทธ์ | D22: วันชัย | E22: พัทธ์ วันชัย | F22: 18631 | G22: 2.07 | K22: 99.38 | L22: 11 | M22: 11 | N22: 2.06 | O22: 15 | P22: 15 | Q22: 1.93 | R22: 15 | S22: 15 | T22: 2.11 | U22: 15 | V22: 15 | W22: 2.08 | X22: 6 | Y22: 6 | Z22: 1.87 | AA22: 6 | AB22: 6 | AC22: 2.62 | AD22: 8.5 | AE22: 8.5 | AF22: 2.5 | AG22: 9 | AH22: 9 | AI22: 1.58 | AJ22: นายมานะ เฉยศรีเทพ | AK22: นางสาวบี วันชัย | AL22: 237134 | AM22: 2563 | AN22: 2 | AO22: ม.3/1 | AP22: 17 | AQ22: 1 | AR22: 35 | AS22: 1 | AT22: 404 | AU22: 242657 | AV22: 242657 | AW22: จบการศึกษาภาคบังคับ | BC22: ดีเยี่ยม | BD22: ดี | BE22: ผ่าน | BF22: ซอยแอนเน็กซ์(กาญจนาภิเษก ๒) | BG22: กรุงเทพมหานคร
A23: 1-7498-00401-49-2 | B23: นาย | C23: พีระพนธ์ | D23: ปะวะโพตะโก | E23: พีระพนธ์ ปะวะโพตะโก | F23: 18632 | G23: 1.99 | K23: 99.38 | L23: 11 | M23: 11 | N23: 1.88 | O23: 15 | P23: 15 | Q23: 1.45 | R23: 15 | S23: 15 | T23: 2.06 | U23: 15 | V23: 15 | W23: 2.15 | X23: 6 | Y23: 6 | Z23: 2.16 | AA23: 6 | AB23: 6 | AC23: 2.45 | AD23: 8.5 | AE23: 8.5 | AF23: 2.38 | AG23: 9 | AH23: 9 | AI23: 1.5 | AJ23: นายประสิทธิ์ ปะวะโพตะโก | AK23: นางสาวคำใหม่ รัตนศรี | AL23: 237048 | AM23: 2563 | AN23: 2 | AO23: ม.3/1 | AP23: 18 | AQ23: 1 | AR23: 35 | AS23: 1 | AT23: 404 | AU23: 242657 | AV23: 242657 | AW23: จบการศึกษาภาคบังคับ | BC23: ดีเยี่ยม | BD23: ดี | BE23: ผ่าน | BF23: วัดเกตุประภา | BG23: ปทุมธานี
A24: 1-1042-00490-70-3 | B24: นาย | C24: ภาณุวิชญ์ | D24: มุขขันธ์ | E24: ภาณุวิชญ์ มุขขันธ์ | F24: 18633 | G24: 2.59 | K24: 99.38 | L24: 11 | M24: 11 | N24: 2.86 | O24: 15 | P24: 15 | Q24: 2 | R24: 15 | S24: 15 | T24: 2.58 | U24: 15 | V24: 15 | W24: 2.68 | X24: 6 | Y24: 6 | Z24: 2.95 | AA24: 6 | AB24: 6 | AC24: 2.83 | AD24: 8.5 | AE24: 8.5 | AF24: 2.82 | AG24: 9 | AH24: 9 | AI24: 2.33 | AJ24: นายจักรี มุขขันธ์ | AK24: นางสาวอัญชัญ ฟ้อนพันธ์ | AL24: 236985 | AM24: 2563 | AN24: 2 | AO24: ม.3/1 | AP24: 19 | AQ24: 1 | AR24: 35 | AS24: 1 | AT24: 404 | AU24: 242622 | AV24: 242622 | AW24: จบการศึกษาภาคบังคับ | BC24: ดีเยี่ยม | BD24: ดีเยี่ยม | BE24: ผ่าน | BF24: ประเทืองทิพย์วิทยา | BG24: กรุงเทพมหานคร
A25: 1-1034-00108-23-2 | B25: เด็กชาย | C25: ภูมิพัฒน์ | D25: กฤษฏิ์ชยานนท์ | E25: ภูมิพัฒน์ กฤษฏิ์ชยานนท์ | F25: 18634 | G25: 2.09 | K25: 99.38 | L25: 11 | M25: 11 | N25: 1.93 | O25: 15 | P25: 15 | Q25: 2.33 | R25: 15 | S25: 15 | T25: 2.15 | U25: 15 | V25: 15 | W25: 2.18 | X25: 6 | Y25: 6 | Z25: 2.04 | AA25: 6 | AB25: 6 | AC25: 2.5 | AD25: 8.5 | AE25: 8.5 | AF25: 1.85 | AG25: 9 | AH25: 9 | AI25: 1.58 | AJ25: นายธวัชชัย สวนโคกกลาง | AK25: นางสาวนัท์นภัส กฤษฏิ์ชยานนท์ | AL25: 237234 | AM25: 2563 | AN25: 2 | AO25: ม.3/1 | AP25: 20 | AQ25: 1 | AR25: 35 | AS25: 1 | AT25: 404 | AU25: 242657 | AV25: 242657 | AW25: จบการศึกษาภาคบังคับ | BC25: ดีเยี่ยม | BD25: ดี | BE25: ผ่าน | BF25: ปิยวัฒนศาสตร์ | BG25: ปทุมธานี
A26: 1-1398-00108-39-1 | B26: เด็กชาย | C26: มงคล | D26: งามวงษ์ | E26: มงคล งามวงษ์ | F26: 18635 | G26: 2.67 | K26: 99.38 | L26: 11 | M26: 11 | N26: 2.93 | O26: 15 | P26: 15 | Q26: 1.96 | R26: 15 | S26: 15 | T26: 2.66 | U26: 15 | V26: 15 | W26: 2.78 | X26: 6 | Y26: 6 | Z26: 2.75 | AA26: 6 | AB26: 6 | AC26: 3.2 | AD26: 8.5 | AE26: 8.5 | AF26: 3.05 | AG26: 9 | AH26: 9 | AI26: 2.33 | AJ26: นายประภาส งามวงษ์ | AK26: นางสาวเดือน คล้านบุญมี | AL26: 237175 | AM26: 2563 | AN26: 2 | AO26: ม.3/1 | AP26: 21 | AQ26: 1 | AR26: 35 | AS26: 1 | AT26: 404 | AU26: 242622 | AV26: 242622 | AW26: จบการศึกษาภาคบังคับ | BC26: ดีเยี่ยม | BD26: ดีเยี่ยม | BE26: ผ่าน | BF26: สหราษฎร์บำรุง | BG26: ปทุมธานี
A27: 1-2705-01106-90-8 | B27: นาย | C27: รัชพล | D27: ฟองฤทธิ์ | E27: รัชพล ฟองฤทธิ์ | F27: 18636 | G27: 2.26 | K27: 99.38 | L27: 11 | M27: 11 | N27: 1.54 | O27: 15 | P27: 15 | Q27: 2.18 | R27: 15 | S27: 15 | T27: 2.25 | U27: 15 | V27: 15 | W27: 2.33 | X27: 6 | Y27: 6 | Z27: 2.91 | AA27: 6 | AB27: 6 | AC27: 3 | AD27: 8.5 | AE27: 8.5 | AF27: 2.73 | AG27: 9 | AH27: 9 | AI27: 1.58 | AJ27: นายสมศักดิ์ ฟองฤทธิ์ | AK27: นางสาวพรพรรณ ชังฟอก | AL27: 236825 | AM27: 2563 | AN27: 2 | AO27: ม.3/1 | AP27: 22 | AQ27: 1 | AR27: 35 | AS27: 1 | AT27: 404 | AU27: 242622 | AV27: 242622 | AW27: จบการศึกษาภาคบังคับ | BC27: ดีเยี่ยม | BD27: ดี | BE27: ผ่าน | BF27: วัดกลางคลองสี่ | BG27: ปทุมธานี
A28: 1-3499-01376-51-9 | B28: นาย | C28: รัฐธีร์ | D28: วิริยะพัฒนศิริ | E28: รัฐธีร์ วิริยะพัฒนศิริ | F28: 18637 | G28: 2.62 | K28: 99.38 | L28: 11 | M28: 11 | N28: 2.22 | O28: 15 | P28: 15 | Q28: 2.71 | R28: 15 | S28: 15 | T28: 2.65 | U28: 15 | V28: 15 | W28: 2.93 | X28: 6 | Y28: 6 | Z28: 2.75 | AA28: 6 | AB28: 6 | AC28: 3.04 | AD28: 8.5 | AE28: 8.5 | AF28: 2.67 | AG28: 9 | AH28: 9 | AI28: 2 | AJ28: นายภาณุวัฒน์ วิริยะพัฒนศิริ | AK28: นางสาววิยะดา ป้องญาติ | AL28: 236932 | AM28: 2563 | AN28: 2 | AO28: ม.3/1 | AP28: 23 | AQ28: 1 | AR28: 35 | AS28: 1 | AT28: 404 | AU28: 242622 | AV28: 242622 | AW28: จบการศึกษาภาคบังคับ | BC28: ดีเยี่ยม | BD28: ดี | BE28: ผ่าน | BF28: จุฑารัตน์วิทยา | BG28: ปทุมธานี
... A41: 1-1029-00090-21-8 | B41: เด็กชาย | C41: ชนะภูมิ | D41: ทองคำวรรณ | E41: ชนะภูมิ ทองคำวรรณ | F41: 18655 | G41: 1.74 | K41: 99.38 | L41: 11 | M41: 11 | N41: 1.11 | O41: 15 | P41: 15 | Q41: 1.38 | R41: 15 | S41: 15 | T41: 1.8 | U41: 15 | V41: 15 | W41: 1.86 | X41: 6 | Y41: 6 | Z41: 1.87 | AA41: 6 | AB41: 6 | AC41: 2.7 | AD41: 8.5 | AE41: 8.5 | AF41: 1.7 | AG41: 9 | AH41: 9 | AI41: 1.75 | AJ41: นายกิตติศักดิ์ สืบสวน | AK41: นางสาวปราณีตา ทองคำวรรณ | AL41: 237106 | AM41: 2563 | AN41: 2 | AO41: ม.3/2 | AP41: 4 | AQ41: 1 | AR41: 32 | AS41: 1 | AT41: 404 | AU41: 242622 | AV41: 242622 | AW41: จบการศึกษาภาคบังคับ | BC41: ดี | BD41: ดี | BE41: ผ่าน | BF41: วัดกลางคลองสี่ | BG41: ปทุมธานี
A42: 1-1037-04005-21-2 | B42: นาย | C42: ชรินทร์ | D42: ยะสุตา | E42: ชรินทร์ ยะสุตา | F42: 18656 | G42: 1.7 | K42: 99.38 | L42: 11 | M42: 9.5 | N42: 1.18 | O42: 13.5 | P42: 12.5 | Q42: 1.24 | R42: 15 | S42: 12 | T42: 1.75 | U42: 15 | V42: 14 | W42: 1.48 | X42: 6 | Y42: 6 | Z42: 2.16 | AA42: 6 | AB42: 5 | AC42: 2.04 | AD42: 8.5 | AE42: 8.5 | AF42: 2 | AG42: 9 | AH42: 9 | AI42: 2.08 | AJ42: นายนรินทร์ ยะสุตา | AK42: นางจิราพรรณ ยะสุตา | AL42: 236875 | AM42: 2563 | AN42: 2 | AO42: ม.3/2 | AP42: 5 | AQ42: 1 | AR42: 32 | AS42: 1 | AT42: 404 | BC42: ดี | BD42: ดี | BE42: ผ่าน | BF42: เฟื่องฟ้าวิทยา | BG42: ปทุมธานี
A43: 1-1010-00135-40-1 | B43: นาย | C43: ฌานยุต | D43: สอนลี | E43: ฌานยุต สอนลี | F43: 18657 | G43: 3.51 | K43: 99.38 | L43: 11 | M43: 11 | N43: 3.72 | O43: 15 | P43: 15 | Q43: 3.66 | R43: 15 | S43: 15 | T43: 3.66 | U43: 15 | V43: 15 | W43: 3.3 | X43: 6 | Y43: 6 | Z43: 3.5 | AA43: 6 | AB43: 6 | AC43: 3.7 | AD43: 8.5 | AE43: 8.5 | AF43: 3.7 | AG43: 9 | AH43: 9 | AI43: 2.83 | AJ43: นายทศพร ดำรงศักดิ์ | AK43: นางสาวณภัทรกาญจน์ สอนลี | AL43: 237058 | AM43: 2563 | AN43: 2 | AO43: ม.3/2 | AP43: 6 | AQ43: 1 | AR43: 32 | AS43: 1 | AT43: 404 | AU43: 242622 | AV43: 242622 | AW43: จบการศึกษาภาคบังคับ | BC43: ดีเยี่ยม | BD43: ดีเยี่ยม | BE43: ผ่าน | BF43: มีนบุรีศึกษา | BG43: กรุงเทพมหานคร
A44: 1-1396-00354-76-3 | B44: นาย | C44: ณัฐพงษ์ | D44: เศษสามารถ | E44: ณัฐพงษ์ เศษสามารถ | F44: 18659 | G44: 1.33 | K44: 99.38 | L44: 11 | M44: 9.5 | N44: 1.27 | O44: 15 | P44: 12.5 | Q44: 0.88 | R44: 15 | S44: 12 | T44: 1.11 | U44: 15 | V44: 14.5 | W44: 1.4 | X44: 6 | Y44: 6 | Z44: 2.2 | AA44: 6 | AB44: 5.5 | AC44: 1.54 | AD44: 8.5 | AE44: 7 | AF44: 1.7 | AG44: 9 | AH44: 6 | AI44: 0.83 | AJ44: นายอุทัย เศษสามารถ | AK44: นางสาวพัฒนา ศรีชมภู | AL44: 237078 | AM44: 2563 | AN44: 2 | AO44: ม.3/2 | AP44: 7 | AQ44: 1 | AR44: 32 | AS44: 1 | AT44: 404 | BC44: ดี | BD44: ดี | BE44: ผ่าน | BF44: วัดเกิดการอุดม | BG44: ปทุมธานี
A45: 1-1397-00048-02-8 | B45: นาย | C45: ธนกฤต | D45: นครศรี | E45: ธนกฤต นครศรี | F45: 18662 | G45: 3.13 | K45: 99.38 | L45: 11 | M45: 11 | N45: 3.22 | O45: 15 | P45: 15 | Q45: 3.38 | R45: 15 | S45: 15 | T45: 3.28 | U45: 15 | V45: 15 | W45: 2.83 | X45: 6 | Y45: 6 | Z45: 3.41 | AA45: 6 | AB45: 6 | AC45: 3.45 | AD45: 8.5 | AE45: 8.5 | AF45: 3.23 | AG45: 9 | AH45: 9 | AI45: 2.25 | AJ45: นายประชัญ นครศรี | AK45: นางสาวกาญจนา สถิตสุข | AL45: 237008 | AM45: 2563 | AN45: 2 | AO45: ม.3/2 | AP45: 8 | AQ45: 1 | AR45: 32 | AS45: 1 | AT45: 404 | AU45: 242622 | AV45: 242622 | AW45: จบการศึกษาภาคบังคับ | BC45: ดีเยี่ยม | BD45: ดีเยี่ยม | BE45: ผ่าน | BF45: ชุมชนเลิศพินิจพิทยาคม | BG45: ปทุมธานี
A46: 1-1042-00514-78-5 | B46: เด็กชาย | C46: ปฐมพร | D46: อุ่มวงศ์ | E46: ปฐมพร อุ่มวงศ์ | F46: 18663 | G46: 1.76 | K46: 99.38 | L46: 11 | M46: 11 | N46: 1.7 | O46: 15 | P46: 15 | Q46: 1.43 | R46: 15 | S46: 15 | T46: 1.48 | U46: 15 | V46: 15 | W46: 1.83 | X46: 6 | Y46: 6 | Z46: 2.16 | AA46: 6 | AB46: 6 | AC46: 2.37 | AD46: 8.5 | AE46: 8.5 | AF46: 2.11 | AG46: 9 | AH46: 9 | AI46: 1.33 | AJ46: นายธีลาพล อุ่มวงศ์ | AK46: นางสาวสุนิษา เชื้อสายมธุรส | AL46: 237147 | AM46: 2563 | AN46: 2 | AO46: ม.3/2 | AP46: 9 | AQ46: 1 | AR46: 32 | AS46: 1 | AT46: 404 | AU46: 242657 | AV46: 242657 | AW46: จบการศึกษาภาคบังคับ | BC46: ดี | BD46: ดี | BE46: ผ่าน | BF46: ปิยวัฒนศาสตร์ | BG46: ปทุมธานี
A47: 1-1397-00051-64-9 | B47: เด็กชาย | C47: ปรัชญา | D47: อินทโชติ | E47: ปรัชญา อินทโชติ | F47: 18664 | G47: 1.62 | K47: 99.38 | L47: 11 | M47: 11 | N47: 1.45 | O47: 15 | P47: 15 | Q47: 1.2 | R47: 15 | S47: 15 | T47: 1.51 | U47: 15 | V47: 15 | W47: 1.45 | X47: 6 | Y47: 6 | Z47: 2.41 | AA47: 6 | AB47: 6 | AC47: 2.62 | AD47: 8.5 | AE47: 8.5 | AF47: 1.67 | AG47: 9 | AH47: 9 | AI47: 1.41 | AJ47: นายปริญญา อินทโชติ | AK47: นางสาวรัชนี อ่ำหนองบัว | AL47: 237130 | AM47: 2563 | AN47: 2 | AO47: ม.3/2 | AP47: 10 | AQ47: 1 | AR47: 32 | AS47: 1 | AT47: 404 | AU47: 242657 | AV47: 242657 | AW47: จบการศึกษาภาคบังคับ | BC47: ดี | BD47: ดี | BE47: ผ่าน | BF47: วัดสุวรรณ | BG47: ปทุมธานี
